Workbook

Sheet Resumo
A1: RESUMO - ESTHER DISTRIBUIDORA DE PEÇAS LTDA
A3: Classe | B3: Itens na curva | C3: COMPRA | D3: NÃO COMPRA | E3: % Compra | F3: Valor do pedido (R$)
A4: A | B4: =COUNTIF(Curva!$F:$F,A4) -> 304 | C4: =COUNTIFS(Curva!$F:$F,A4,Curva!$C:$C,"COMPRA") -> 15 | D4: =B4-C4 -> 289 | E4: =C4/B4 -> 0.049342105 | F4: =SUMIFS(Curva!$E:$E,Curva!$F:$F,A4) -> 10386.8
A5: B | B5: =COUNTIF(Curva!$F:$F,A5) -> 399 | C5: =COUNTIFS(Curva!$F:$F,A5,Curva!$C:$C,"COMPRA") -> 4 | D5: =B5-C5 -> 395 | E5: =C5/B5 -> 0.010025063 | F5: =SUMIFS(Curva!$E:$E,Curva!$F:$F,A5) -> 3131.36
A6: C | B6: =COUNTIF(Curva!$F:$F,A6) -> 999 | C6: =COUNTIFS(Curva!$F:$F,A6,Curva!$C:$C,"COMPRA") -> 6 | D6: =B6-C6 -> 993 | E6: =C6/B6 -> 0.006006006 | F6: =SUMIFS(Curva!$E:$E,Curva!$F:$F,A6) -> 3993.42
A7: TOTAL | B7: =SUM(B4:B6) -> 1702 | C7: =SUM(C4:C6) -> 25 | D7: =SUM(D4:D6) -> 1677 | E7: =C7/B7 -> 0.014688602 | F7: =SUM(F4:F6) -> 17511.58

Sheet Curva
A1: Código | B1: CÓDIGO NO PEDIDO (PROCV) | C1: COMPRA / NÃO COMPRA | D1: QTD PEDIDO | E1: VALOR PEDIDO | F1: Classe | G1: Produto | H1: Familia | I1: Montadora | J1: Cross | K1: Total (histórico) | L1: % Acumulado | M1: AK (RELATÓRIO) | N1: CONFERE c/ TOTAL | O1: APLICAÇÃO (LISTA) | P1: PRODUTO (LISTA)
A2: SSC3020 | B2: =IFERROR(VLOOKUP(A2,Pedido!$A:$B,2,0),"") | C2: =IF(B2="","NÃO COMPRA","COMPRA") -> NÃO COMPRA | D2: =IFERROR(VLOOKUP(A2,Pedido!$A:$C,3,0),0) -> 0 | E2: =IFERROR(VLOOKUP(A2,Pedido!$A:$E,5,0),0) -> 0 | F2: A | G2: CILINDRO AUXILIAR DE EMBREAGEM HYUNDAI | H2: CILINDRO AUXILIAR DE EMBREAGEM | I2: HYUNDAI | K2: 15657 | L2: 0.02676607 | M2: =SUMIF(Relatorio_AK!$A:$A,A2,Relatorio_AK!$B:$B) -> 15657 | N2: =IF(M2=K2,"OK","DIF") -> OK | O2: =IFERROR(VLOOKUP($A2,Lista_Starke!$A:$E,3,0),"NÃO ESTÁ NA LISTA") -> HYUNDAI: HB20 1.0 12V 12/... | P2: =IFERROR(VLOOKUP($A2,Lista_Starke!$A:$E,2,0),"NÃO ESTÁ NA LISTA") -> CILINDRO AUXILIAR DE EMBREAGEM
A3: SCC2064 | B3: =IFERROR(VLOOKUP(A3,Pedido!$A:$B,2,0),"") | C3: =IF(B3="","NÃO COMPRA","COMPRA") -> NÃO COMPRA | D3: =IFERROR(VLOOKUP(A3,Pedido!$A:$C,3,0),0) -> 0 | E3: =IFERROR(VLOOKUP(A3,Pedido!$A:$E,5,0),0) -> 0 | F3: A | G3: CILINDRO MESTRE DE EMBREAGEM HYUNDAI | H3: CILINDRO MESTRE DE EMBREAGEM | I3: HYUNDAI | K3: 14311 | L3: 0.051231116 | M3: =SUMIF(Relatorio_AK!$A:$A,A3,Relatorio_AK!$B:$B) -> 14311 | N3: =IF(M3=K3,"OK","DIF") -> OK | O3: =IFERROR(VLOOKUP($A3,Lista_Starke!$A:$E,3,0),"NÃO ESTÁ NA LISTA") -> HYUNDAI: HB20 1.0 12V 3 cil 12/... HYUNDAI: HB20 1.6 16V 12/... | P3: =IFERROR(VLOOKUP($A3,Lista_Starke!$A:$E,2,0),"NÃO ESTÁ NA LISTA") -> CILINDRO MESTRE DE EMBREAGEM
A4: SBC1000 | B4: =IFERROR(VLOOKUP(A4,Pedido!$A:$B,2,0),"") | C4: =IF(B4="","NÃO COMPRA","COMPRA") -> NÃO COMPRA | D4: =IFERROR(VLOOKUP(A4,Pedido!$A:$C,3,0),0) -> 0 | E4: =IFERROR(VLOOKUP(A4,Pedido!$A:$E,5,0),0) -> 0 | F4: A | G4: CILINDRO MESTRE DE FREIO VW | H4: CILINDRO MESTRE DE FREIO | I4: VOLKSWAGEN | J4: 5109 (ATE) | C2003 (CONTROIL) | RCCM23314 (TRW) | K4: 6588 | L4: 0.062493482 | M4: =SUMIF(Relatorio_AK!$A:$A,A4,Relatorio_AK!$B:$B) -> 6588 | N4: =IF(M4=K4,"OK","DIF") -> OK | O4: =IFERROR(VLOOKUP($A4,Lista_Starke!$A:$E,3,0),"NÃO ESTÁ NA LISTA") -> VOLKSWAGEN: Fusca 1.3 67/76 | P4: =IFERROR(VLOOKUP($A4,Lista_Starke!$A:$E,2,0),"NÃO ESTÁ NA LISTA") -> CILINDRO MESTRE DE FREIO
A5: SBC1090A | B5: =IFERROR(VLOOKUP(A5,Pedido!$A:$B,2,0),"") | C5: =IF(B5="","NÃO COMPRA","COMPRA") -> NÃO COMPRA | D5: =IFERROR(VLOOKUP(A5,Pedido!$A:$C,3,0),0) -> 0 | E5: =IFERROR(VLOOKUP(A5,Pedido!$A:$E,5,0),0) -> 0 | F5: A | G5: CILINDRO MESTRE FREIO VW | H5: CILINDRO MESTRE DE FREIO | I5: VOLKSWAGEN | K5: 6193 | L5: 0.073080585 | M5: =SUMIF(Relatorio_AK!$A:$A,A5,Relatorio_AK!$B:$B) -> 6193 | N5: =IF(M5=K5,"OK","DIF") -> OK | O5: =IFERROR(VLOOKUP($A5,Lista_Starke!$A:$E,3,0),"NÃO ESTÁ NA LISTA") -> VOLKSWAGEN: Gol G6 1.0 / 1.6 13/... VOLKSWAGEN: Gol G7 1.0 / 1.6 17/... VOLKSWAGEN: Nivus 1.0 TSI 20/... VOLKSWAGEN: Polo 1.0 TSI / 1.6 MSI 17/... VOLKSWAGEN: Saveiro G6 1.6 MSI 13/... VOLKSWAGEN: T-Cross 1.0 TSI 19/... VOLKSWAGEN: Up 1.0 12V / 1.0 TSI 14/... VOLKSWAGEN: Virtus 1.0 TSI / 1.6 MSI 18/... VOLKSWAGEN: Voyage G6 1.0 / 1.6 13/... | P5: =IFERROR(VLOOKUP($A5,Lista_Starke!$A:$E,2,0),"NÃO ESTÁ NA LISTA") -> CILINDRO MESTRE DE FREIO
A6: SBC1001 | B6: =IFERROR(VLOOKUP(A6,Pedido!$A:$B,2,0),"") | C6: =IF(B6="","NÃO COMPRA","COMPRA") -> NÃO COMPRA | D6: =IFERROR(VLOOKUP(A6,Pedido!$A:$C,3,0),0) -> 0 | E6: =IFERROR(VLOOKUP(A6,Pedido!$A:$E,5,0),0) -> 0 | F6: A | G6: CILINDRO MESTRE DE FREIO RENAULT | H6: CILINDRO MESTRE DE FREIO | I6: RENAULT | J6: 0986AB8673 (BOSCH) | 7701205740 (OEM) | 7701205815 (OEM) | C2096 (CONTROIL) | K6: 5930 | L6: 0.083218083 | M6: =SUMIF(Relatorio_AK!$A:$A,A6,Relatorio_AK!$B:$B) -> 5930 | N6: =IF(M6=K6,"OK","DIF") -> OK | O6: =IFERROR(VLOOKUP($A6,Lista_Starke!$A:$E,3,0),"NÃO ESTÁ NA LISTA") -> RENAULT: Clio 1.0 / 1.6 00/... RENAULT: Kangoo 1.0 / 1.6 00/... RENAULT: Symbol 1.0 / 1.6 09/... | P6: =IFERROR(VLOOKUP($A6,Lista_Starke!$A:$E,2,0),"NÃO ESTÁ NA LISTA") -> CILINDRO MESTRE DE FREIO
A7: SBC1137 | B7: =IFERROR(VLOOKUP(A7,Pedido!$A:$B,2,0),"") | C7: =IF(B7="","NÃO COMPRA","COMPRA") -> NÃO COMPRA | D7: =IFERROR(VLOOKUP(A7,Pedido!$A:$C,3,0),0) -> 0 | E7: =IFERROR(VLOOKUP(A7,Pedido!$A:$E,5,0),0) -> 0 | F7: A | G7: CILIDNRO MESTRE DE FREIO FIAT | H7: CILINDRO MESTRE DE FREIO | I7: FIAT | J7: 0204798525 (BOSCH) | K7: 5587 | L7: 0.092769212 | M7: =SUMIF(Relatorio_AK!$A:$A,A7,Relatorio_AK!$B:$B) -> 5587 | N7: =IF(M7=K7,"OK","DIF") -> OK | O7: =IFERROR(VLOOKUP($A7,Lista_Starke!$A:$E,3,0),"NÃO ESTÁ NA LISTA") -> FIAT: Grand Siena 1.4 8V Fire EVO 12/... FIAT: Grand Siena 1.6 16V Etorq 12/... FIAT: Grand Siena 1.6 16V Etorq Dualogic 12/... FIAT: Palio 1.0 8V Fire EVO 12/... FIAT: Palio 1.4 8V Fire EVO 12/... FIAT: Palio 1.6 16V Etorq 12/... FIAT: Palio 1.6 16V Etorq Dualogic 12/... FIAT: Uno 1.0 8V Fire EVO 12/... FIAT: Uno 1.4 8V Fire EVO 12/... | P7: =IFERROR(VLOOKUP($A7,Lista_Starke!$A:$E,2,0),"NÃO ESTÁ NA LISTA") -> CILNDRO MESTRE DE FREIO
A8: SCC2017 | B8: =IFERROR(VLOOKUP(A8,Pedido!$A:$B,2,0),"") -> SCC 2017 | C8: =IF(B8="","NÃO COMPRA","COMPRA") -> COMPRA | D8: =IFERROR(VLOOKUP(A8,Pedido!$A:$C,3,0),0) -> 1 | E8: =IFERROR(VLOOKUP(A8,Pedido!$A:$E,5,0),0) -> 95 | F8: A | G8: CILINDRO MESTRE DE EMBREAGEM HONDA | H8: CILINDRO MESTRE DE EMBREAGEM | I8: HONDA | K8: 5428 | L8: 0.10204853 | M8: =SUMIF(Relatorio_AK!$A:$A,A8,Relatorio_AK!$B:$B) -> 5428 | N8: =IF(M8=K8,"OK","DIF") -> OK | O8: =IFERROR(VLOOKUP($A8,Lista_Starke!$A:$E,3,0),"NÃO ESTÁ NA LISTA") -> HONDA: City 1.5 16V 09/... HONDA: Fit 1.4 16V / 1.5 16V 09/... | P8: =IFERROR(VLOOKUP($A8,Lista_Starke!$A:$E,2,0),"NÃO ESTÁ NA LISTA") -> CILINDRO MESTRE DE EMBREAGEM
A9: SBC1068 | B9: =IFERROR(VLOOKUP(A9,Pedido!$A:$B,2,0),"") | C9: =IF(B9="","NÃO COMPRA","COMPRA") -> NÃO COMPRA | D9: =IFERROR(VLOOKUP(A9,Pedido!$A:$C,3,0),0) -> 0 | E9: =IFERROR(VLOOKUP(A9,Pedido!$A:$E,5,0),0) -> 0 | F9: A | G9: CILINDRO MESTRE DE FREIO FORD | H9: CILINDRO MESTRE DE FREIO | I9: FORD | J9: 2S652140CA (OEM) | 6168 (ATE) | C2155 (CONTROIL) | K9: 5372 | L9: 0.11123211 | M9: =SUMIF(Relatorio_AK!$A:$A,A9,Relatorio_AK!$B:$B) -> 5372 | N9: =IF(M9=K9,"OK","DIF") -> OK | O9: =IFERROR(VLOOKUP($A9,Lista_Starke!$A:$E,3,0),"NÃO ESTÁ NA LISTA") -> FORD: Ecosport 03/12 FORD: Fiesta 03/... | P9: =IFERROR(VLOOKUP($A9,Lista_Starke!$A:$E,2,0),"NÃO ESTÁ NA LISTA") -> CILINDRO MESTRE DE FREIO
A10: SBC1123 | B10: =IFERROR(VLOOKUP(A10,Pedido!$A:$B,2,0),"") | C10: =IF(B10="","NÃO COMPRA","COMPRA") -> NÃO COMPRA | D10: =IFERROR(VLOOKUP(A10,Pedido!$A:$C,3,0),0) -> 0 | E10: =IFERROR(VLOOKUP(A10,Pedido!$A:$E,5,0),0) -> 0 | F10: A | G10: CILINDRO MESTRE DE FREIO GM | H10: CILINDRO MESTRE DE FREIO | I10: GM | J10: 6989 (ATE) | 94756709 (OEM) | C2220 (CONTROIL) | K10: 4985 | L10: 0.1197541 | M10: =SUMIF(Relatorio_AK!$A:$A,A10,Relatorio_AK!$B:$B) -> 4985 | N10: =IF(M10=K10,"OK","DIF") -> OK | O10: =IFERROR(VLOOKUP($A10,Lista_Starke!$A:$E,3,0),"NÃO ESTÁ NA LISTA") -> GM: Celta 1.0 8V 14/16 GM: Corsa Classic 1.0 V 12/... GM: Corsa Classic 1.4 8V 12/... | P10: =IFERROR(VLOOKUP($A10,Lista_Starke!$A:$E,2,0),"NÃO ESTÁ NA LISTA") -> CILINDRO MESTRE DE FREIO
A11: SBC1087 | B11: =IFERROR(VLOOKUP(A11,Pedido!$A:$B,2,0),"") | C11: =IF(B11="","NÃO COMPRA","COMPRA") -> NÃO COMPRA | D11: =IFERROR(VLOOKUP(A11,Pedido!$A:$C,3,0),0) -> 0 | E11: =IFERROR(VLOOKUP(A11,Pedido!$A:$E,5,0),0) -> 0 | F11: A | G11: CILINDRO MESTRE DE FREIO RENAULT | H11: CILINDRO MESTRE DE FREIO | I11: RENAULT | J11: 460118760R (OEM) | 6001551613 (OEM) | 6967 (ATE) | C-2178 (CONTROIL) | K11: 4922 | L11: 0.1281684 | M11: =SUMIF(Relatorio_AK!$A:$A,A11,Relatorio_AK!$B:$B) -> 4922 | N11: =IF(M11=K11,"OK","DIF") -> OK | O11: =IFERROR(VLOOKUP($A11,Lista_Starke!$A:$E,3,0),"NÃO ESTÁ NA LISTA") -> RENAULT: Logan 1.0 / 1.6 07/13 RENAULT: Sandero 1.0 / 1.6 07/14 | P11: =IFERROR(VLOOKUP($A11,Lista_Starke!$A:$E,2,0),"NÃO ESTÁ NA LISTA") -> CILINDRO MESTRE DE FREIO
A12: SCC2060 | B12: =IFERROR(VLOOKUP(A12,Pedido!$A:$B,2,0),"") | C12: =IF(B12="","NÃO COMPRA","COMPRA") -> NÃO COMPRA | D12: =IFERROR(VLOOKUP(A12,Pedido!$A:$C,3,0),0) -> 0 | E12: =IFERROR(VLOOKUP(A12,Pedido!$A:$E,5,0),0) -> 0 | F12: A | G12: CILINDRO MESTRE DE EMBREAGEM RENAULT | H12: CILINDRO MESTRE DE EMBREAGEM | I12: NISSAN / RENAULT | K12: 4719 | L12: 0.13623565 | M12: =SUMIF(Relatorio_AK!$A:$A,A12,Relatorio_AK!$B:$B) -> 4719 | N12: =IF(M12=K12,"OK","DIF") -> OK | O12: =IFERROR(VLOOKUP($A12,Lista_Starke!$A:$E,3,0),"NÃO ESTÁ NA LISTA") -> NISSAN: March 1.0 16V 11/... NISSAN: March 1.6 16V 11/... NISSAN: Versa 1.6 16V 11/... RENAULT: Captur 1.6 16V 17/... RENAULT: Duster 1.6 / 2.0 16/... RENAULT: Logan 1.6 16V 13/16 RENAULT: Logan 1.6 16V 17/... RENAULT: Oroch 1.6 16V 16/... RENAULT: Sandero 1.6 16V 13/16 RENAULT: Sandero 1.6 16V 17/... | P12: =IFERROR(VLOOKUP($A12,Lista_Starke!$A:$E,2,0),"NÃO ESTÁ NA LISTA") -> CILINDRO MESTRE DE EMBREAGEM
A13: SBC1014 | B13: =IFERROR(VLOOKUP(A13,Pedido!$A:$B,2,0),"") | C13: =IF(B13="","NÃO COMPRA","COMPRA") -> NÃO COMPRA | D13: =IFERROR(VLOOKUP(A13,Pedido!$A:$C,3,0),0) -> 0 | E13: =IFERROR(VLOOKUP(A13,Pedido!$A:$E,5,0),0) -> 0 | F13: A | G13: CILINDRO MESTRE DE FREIO FIAT | H13: CILINDRO MESTRE DE FREIO | I13: FIAT | J13: 5785 (ATE) | 7079433 (OEM) | C2075 (CONTROIL) | RCCD01530 (TRW) | K13: 4390 | L13: 0.14374048 | M13: =SUMIF(Relatorio_AK!$A:$A,A13,Relatorio_AK!$B:$B) -> 4390 | N13: =IF(M13=K13,"OK","DIF") -> OK | O13: =IFERROR(VLOOKUP($A13,Lista_Starke!$A:$E,3,0),"NÃO ESTÁ NA LISTA") -> FIAT: Fiorino 94/... FIAT: Palio 98/... FIAT: Palio Weekend 98/... FIAT: Siena 98/... FIAT: Strada 98/... | P13: =IFERROR(VLOOKUP($A13,Lista_Starke!$A:$E,2,0),"NÃO ESTÁ NA LISTA") -> CILINDRO MESTRE DE FREIO
A14: SBC1007 | B14: =IFERROR(VLOOKUP(A14,Pedido!$A:$B,2,0),"") | C14: =IF(B14="","NÃO COMPRA","COMPRA") -> NÃO COMPRA | D14: =IFERROR(VLOOKUP(A14,Pedido!$A:$C,3,0),0) -> 0 | E14: =IFERROR(VLOOKUP(A14,Pedido!$A:$E,5,0),0) -> 0 | F14: A | G14: CILINDRO MESTRE DE FREIO GM | H14: CILINDRO MESTRE DE FREIO | I14: GM | J14: 0986AB8644 (BOSCH) | 5991 (ATE) | 93289332 (OEM) | C2082 (CONTROIL) | RCCD01620 (TRW) | K14: 4235 | L14: 0.15098033 | M14: =SUMIF(Relatorio_AK!$A:$A,A14,Relatorio_AK!$B:$B) -> 4235 | N14: =IF(M14=K14,"OK","DIF") -> OK | O14: =IFERROR(VLOOKUP($A14,Lista_Starke!$A:$E,3,0),"NÃO ESTÁ NA LISTA") -> GM: Agile 10/11 GM: Classic 03/09 GM: Corsa 98/02 GM: Montana 11/13 | P14: =IFERROR(VLOOKUP($A14,Lista_Starke!$A:$E,2,0),"NÃO ESTÁ NA LISTA") -> CILINDRO MESTRE DE FREIO
A15: SBC1011 | B15: =IFERROR(VLOOKUP(A15,Pedido!$A:$B,2,0),"") -> SBC 1011 | C15: =IF(B15="","NÃO COMPRA","COMPRA") -> COMPRA | D15: =IFERROR(VLOOKUP(A15,Pedido!$A:$C,3,0),0) -> 4 | E15: =IFERROR(VLOOKUP(A15,Pedido!$A:$E,5,0),0) -> 352 | F15: A | G15: CILINDRO MESTRE DE FREIO PEUGEOT | H15: CILINDRO MESTRE DE FREIO | I15: PEUGEOT | J15: 0986AB8648 (BOSCH) | 4601F8 (OEM) | 6071 (ATE) | C2130 (CONTROIL) | PMF494 (TRW) | K15: 4094 | L15: 0.15797913 | M15: =SUMIF(Relatorio_AK!$A:$A,A15,Relatorio_AK!$B:$B) -> 4094 | N15: =IF(M15=K15,"OK","DIF") -> OK | O15: =IFERROR(VLOOKUP($A15,Lista_Starke!$A:$E,3,0),"NÃO ESTÁ NA LISTA") -> PEUGEOT: 206 1.0 16V 01/04 PEUGEOT: 206 1.4 8V 05/10 PEUGEOT: 206 1.6 8V 99/01 PEUGEOT: 206 / 206 SW 1.4 8V 05/08 PEUGEOT: 207 1.4 8V 09/... PEUGEOT: 207 / SW 1.4 8V 09/... PEUGEOT: 306 1.6 94/97 | P15: =IFERROR(VLOOKUP($A15,Lista_Starke!$A:$E,2,0),"NÃO ESTÁ NA LISTA") -> CILINDRO MESTRE DE FREIO
A16: SBC1085 | B16: =IFERROR(VLOOKUP(A16,Pedido!$A:$B,2,0),"") | C16: =IF(B16="","NÃO COMPRA","COMPRA") -> NÃO COMPRA | D16: =IFERROR(VLOOKUP(A16,Pedido!$A:$C,3,0),0) -> 0 | E16: =IFERROR(VLOOKUP(A16,Pedido!$A:$E,5,0),0) -> 0 | F16: A | G16: CILINDRO MESTRE DE FREIO FIAT | H16: CILINDRO MESTRE DE FREIO | I16: FIAT | J16: 7087530 (OEM) | 7402 (ATE) | C2225 (CONTROIL) | K16: 4016 | L16: 0.1648446 | M16: =SUMIF(Relatorio_AK!$A:$A,A16,Relatorio_AK!$B:$B) -> 4016 | N16: =IF(M16=K16,"OK","DIF") -> OK | O16: =IFERROR(VLOOKUP($A16,Lista_Starke!$A:$E,3,0),"NÃO ESTÁ NA LISTA") -> FIAT: Argo 1.0 6V 3 cil. 17/... FIAT: Argo 1.3 8V 17/... FIAT: Argo 1.8 16V 17/... FIAT: Cronos 1.3 8V 18/... FIAT: Cronos 1.8 16V 18/... FIAT: Fiorino 1.4 8V 13/... FIAT: Grand Siena 1.4 8V 12/... FIAT: Grand Siena 1.6 16V 12/... FIAT: Mobi 1.0 8V 16/... FIAT: Palio 1.0 / 1.4 12/... FIAT: Palio 1.6 Etorq 12/... FIAT: Uno 1.0 8V 13/... FIAT: Uno 1.4 8V 13/... | P16: =IFERROR(VLOOKUP($A16,Lista_Starke!$A:$E,2,0),"NÃO ESTÁ NA LISTA") -> CILINDRO MESTRE DE FREIO
A17: SBC1135 | B17: =IFERROR(VLOOKUP(A17,Pedido!$A:$B,2,0),"") | C17: =IF(B17="","NÃO COMPRA","COMPRA") -> NÃO COMPRA | D17: =IFERROR(VLOOKUP(A17,Pedido!$A:$C,3,0),0) -> 0 | E17: =IFERROR(VLOOKUP(A17,Pedido!$A:$E,5,0),0) -> 0 | F17: A | G17: CILINDRO MESTRE DE FREIO CITROEN/PEUGEOT | H17: CILINDRO MESTRE DE FREIO | I17: CITROEN / PEUGEOT | J17: 1613317680 (OEM) | C2260 (CONTROIL) | K17: 3970 | L17: 0.17163142 | M17: =SUMIF(Relatorio_AK!$A:$A,A17,Relatorio_AK!$B:$B) -> 3970 | N17: =IF(M17=K17,"OK","DIF") -> OK | O17: =IFERROR(VLOOKUP($A17,Lista_Starke!$A:$E,3,0),"NÃO ESTÁ NA LISTA") -> CITROEN: 208 1.6 16V EC5 12/19 CITROEN: Aircross 1.5 8V TU5 12/19 CITROEN: Aircross 1.6 16V EC5 12/19 CITROEN: C3 1.5 8V TU5 12/18 CITROEN: C3 1.6 16V EC5 12/19 CITROEN: C3 Picasso 1.6 16V EC5 16/19 PEUGEOT: 2008 1.6 16V EC5 13/19 PEUGEOT: 208 1.5 8V TU5 12/19 | P17: =IFERROR(VLOOKUP($A17,Lista_Starke!$A:$E,2,0),"NÃO ESTÁ NA LISTA") -> CILINDRO MESTRE DE FREIO
A18: SBC1021 | B18: =IFERROR(VLOOKUP(A18,Pedido!$A:$B,2,0),"") | C18: =IF(B18="","NÃO COMPRA","COMPRA") -> NÃO COMPRA | D18: =IFERROR(VLOOKUP(A18,Pedido!$A:$C,3,0),0) -> 0 | E18: =IFERROR(VLOOKUP(A18,Pedido!$A:$E,5,0),0) -> 0 | F18: A | G18: CILINDRO MESTRE DE FREIO FIAT | H18: CILINDRO MESTRE DE FREIO | I18: FIAT | J18: 5766 (ATE) | 7074619 (OEM) | C2033 (CONTROIL) | RCCD00890 (TRW) | K18: 3303 | L18: 0.17727799 | M18: =SUMIF(Relatorio_AK!$A:$A,A18,Relatorio_AK!$B:$B) -> 3303 | N18: =IF(M18=K18,"OK","DIF") -> OK | O18: =IFERROR(VLOOKUP($A18,Lista_Starke!$A:$E,3,0),"NÃO ESTÁ NA LISTA") -> FIAT: Elba 91/96 FIAT: Fiorino 91/93 FIAT: Prêmio 91/96 FIAT: Uno 11/... FIAT: Uno 87/91 FIAT: Uno 91/10 | P18: =IFERROR(VLOOKUP($A18,Lista_Starke!$A:$E,2,0),"NÃO ESTÁ NA LISTA") -> CILINDRO MESTRE DE FREIO
A19: SBC1134 | B19: =IFERROR(VLOOKUP(A19,Pedido!$A:$B,2,0),"") | C19: =IF(B19="","NÃO COMPRA","COMPRA") -> NÃO COMPRA | D19: =IFERROR(VLOOKUP(A19,Pedido!$A:$C,3,0),0) -> 0 | E19: =IFERROR(VLOOKUP(A19,Pedido!$A:$E,5,0),0) -> 0 | F19: A | G19: CILINDRO MESTRE DE FREIO RENAULT | H19: CILINDRO MESTRE DE FREIO | I19: RENAULT | J19: 0204798374 (BOSCH) | 460119216R (OEM) | C2263 (CONTROIL) | K19: 3257 | L19: 0.18284592 | M19: =SUMIF(Relatorio_AK!$A:$A,A19,Relatorio_AK!$B:$B) -> 3257 | N19: =IF(M19=K19,"OK","DIF") -> OK | O19: =IFERROR(VLOOKUP($A19,Lista_Starke!$A:$E,3,0),"NÃO ESTÁ NA LISTA") -> RENAULT: Logan 1.0 16V 13/16 RENAULT: Logan 1.0 3 cil 16/... RENAULT: Logan 1.6 16V 13/16 RENAULT: Logan 1.6 16V 16/... RENAULT: Sandero 1.0 16V 14/16 RENAULT: Sandero 1.0 3 cil 16/... RENAULT: Sandero 1.6 16V 14/16 RENAULT: Sandero 1.6 16V 16/... | P19: =IFERROR(VLOOKUP($A19,Lista_Starke!$A:$E,2,0),"NÃO ESTÁ NA LISTA") -> CILINDRO MESTRE DE FREIO
A20: SBC1090 | B20: =IFERROR(VLOOKUP(A20,Pedido!$A:$B,2,0),"") | C20: =IF(B20="","NÃO COMPRA","COMPRA") -> NÃO COMPRA | D20: =IFERROR(VLOOKUP(A20,Pedido!$A:$C,3,0),0) -> 0 | E20: =IFERROR(VLOOKUP(A20,Pedido!$A:$E,5,0),0) -> 0 | F20: A | G20: CILINDRO MESTRE DE FREIO VW | H20: CILINDRO MESTRE DE FREIO | I20: VOLKSWAGEN | K20: 3160 | L20: 0.18824803 | M20: =SUMIF(Relatorio_AK!$A:$A,A20,Relatorio_AK!$B:$B) -> 3160 | N20: =IF(M20=K20,"OK","DIF") -> OK | O20: =IFERROR(VLOOKUP($A20,Lista_Starke!$A:$E,3,0),"NÃO ESTÁ NA LISTA") -> VOLKSWAGEN: Gol G6 1.0 / 1.6 13/... VOLKSWAGEN: Saveiro G6 1.6 13/... VOLKSWAGEN: Voyage G6 1.0 / 1.6 13/... | P20: =IFERROR(VLOOKUP($A20,Lista_Starke!$A:$E,2,0),"NÃO ESTÁ NA LISTA") -> CILINDRO MESTRE DE FREIO
A21: SBC1081 | B21: =IFERROR(VLOOKUP(A21,Pedido!$A:$B,2,0),"") | C21: =IF(B21="","NÃO COMPRA","COMPRA") -> NÃO COMPRA | D21: =IFERROR(VLOOKUP(A21,Pedido!$A:$C,3,0),0) -> 0 | E21: =IFERROR(VLOOKUP(A21,Pedido!$A:$E,5,0),0) -> 0 | F21: A | G21: CILINDRO MESTRE DE FREIO VW | H21: CILINDRO MESTRE DE FREIO | I21: VOLKSWAGEN | J21: 0986AB8572 (BOSCH) | 5Z0611019N (OEM) | C2160 (CONTROIL) | K21: 3118 | L21: 0.19357833 | M21: =SUMIF(Relatorio_AK!$A:$A,A21,Relatorio_AK!$B:$B) -> 3118 | N21: =IF(M21=K21,"OK","DIF") -> OK | O21: =IFERROR(VLOOKUP($A21,Lista_Starke!$A:$E,3,0),"NÃO ESTÁ NA LISTA") -> VOLKSWAGEN: Crossfox 05/... VOLKSWAGEN: Fox 04/... VOLKSWAGEN: Polo 02/... VOLKSWAGEN: Space Cross 12/... VOLKSWAGEN: Spacefox 06/... | P21: =IFERROR(VLOOKUP($A21,Lista_Starke!$A:$E,2,0),"NÃO ESTÁ NA LISTA") -> CILINDRO MESTRE DE FREIO
A22: SWC5006 | B22: =IFERROR(VLOOKUP(A22,Pedido!$A:$B,2,0),"") | C22: =IF(B22="","NÃO COMPRA","COMPRA") -> NÃO COMPRA | D22: =IFERROR(VLOOKUP(A22,Pedido!$A:$C,3,0),0) -> 0 | E22: =IFERROR(VLOOKUP(A22,Pedido!$A:$E,5,0),0) -> 0 | F22: A | G22: CILINDRO DE RODA LE/LD RENAULT/VW | H22: CILINDRO DE RODA | I22: RENAULT / VOLKSWAGEN | J22: 0986AB8653 (BOSCH) | 6001551410 (OEM) | C3537 (CONTROIL) | CCR92250 (FORTEC) | RCCR03580 (TRW) | K22: 3108 | L22: 0.19889154 | M22: =SUMIF(Relatorio_AK!$A:$A,A22,Relatorio_AK!$B:$B) -> 3108 | N22: =IF(M22=K22,"OK","DIF") -> OK | O22: =IFERROR(VLOOKUP($A22,Lista_Starke!$A:$E,3,0),"NÃO ESTÁ NA LISTA") -> RENAULT: Clio 1.0 16V 12/... RENAULT: Logan 1.6 8V / 1.6 16V 07/13 RENAULT: Sandero 1.6 8V / 1.6 16V 07/13 RENAULT: Symbol 1.6 8V 09/13 VOLKSWAGEN: Gol 1.0 12V 3cil 16/... VOLKSWAGEN: Gol 1.0 8V / 1.6 8V 15/... VOLKSWAGEN: Up 1.0 12V 14/... VOLKSWAGEN: Up 1.0 12V 3cil TSI 14/... VOLKSWAGEN: Voyage 1.6 8V 16/... | P22: =IFERROR(VLOOKUP($A22,Lista_Starke!$A:$E,2,0),"NÃO ESTÁ NA LISTA") -> CILINDRO DE RODA LE/LD
A23: SWC5015 | B23: =IFERROR(VLOOKUP(A23,Pedido!$A:$B,2,0),"") | C23: =IF(B23="","NÃO COMPRA","COMPRA") -> NÃO COMPRA | D23: =IFERROR(VLOOKUP(A23,Pedido!$A:$C,3,0),0) -> 0 | E23: =IFERROR(VLOOKUP(A23,Pedido!$A:$E,5,0),0) -> 0 | F23: A | G23: CILINDRO DE RODA LE/LD GM | H23: CILINDRO DE RODA | I23: GM | J23: 0986AB8667 (BOSCH) | 7630 (ATE) | 93313891 (OEM) | C3521 (CONTROIL) | CCR92241 (FORTEC) | CR2202 (BOSCH) | K23: 3004 | L23: 0.20402696 | M23: =SUMIF(Relatorio_AK!$A:$A,A23,Relatorio_AK!$B:$B) -> 3004 | N23: =IF(M23=K23,"OK","DIF") -> OK | O23: =IFERROR(VLOOKUP($A23,Lista_Starke!$A:$E,3,0),"NÃO ESTÁ NA LISTA") -> GM: Astra 2.0 8V 05/11 GM: Montana 1.4 8V / 1.8 8V 04/... GM: Montana 1.4 8V / 1.8 8V 08/... GM: Vectra 2.0 8V / 2.4 16V 06/11 GM: Zafira 2.0 8V 05/12 | P23: =IFERROR(VLOOKUP($A23,Lista_Starke!$A:$E,2,0),"NÃO ESTÁ NA LISTA") -> CILINDRO DE RODA LE/LD
A24: SVP6031 | B24: =IFERROR(VLOOKUP(A24,Pedido!$A:$B,2,0),"") | C24: =IF(B24="","NÃO COMPRA","COMPRA") -> NÃO COMPRA | D24: =IFERROR(VLOOKUP(A24,Pedido!$A:$C,3,0),0) -> 0 | E24: =IFERROR(VLOOKUP(A24,Pedido!$A:$E,5,0),0) -> 0 | F24: A | G24: BOMBA DE VÁCUO FIAT/JEEP | H24: BOMBA DE VÁCUO | I24: FIAT / JEEP | K24: 2917 | L24: 0.20901365 | M24: =SUMIF(Relatorio_AK!$A:$A,A24,Relatorio_AK!$B:$B) -> 2917 | N24: =IF(M24=K24,"OK","DIF") -> OK | O24: =IFERROR(VLOOKUP($A24,Lista_Starke!$A:$E,3,0),"NÃO ESTÁ NA LISTA") -> FIAT: Toro 2.0 16V JTD Diesel 16/… JEEP: Commander 2.0 16V Turbo Diesel 21/... JEEP: Compass 2.0 16V JTD Diesel 16/… JEEP: Renegade 2.0 16V JTD Diesel 16/… | P24: =IFERROR(VLOOKUP($A24,Lista_Starke!$A:$E,2,0),"NÃO ESTÁ NA LISTA") -> BOMBA DE VÁCUO
A25: SCC2029 | B25: =IFERROR(VLOOKUP(A25,Pedido!$A:$B,2,0),"") -> SCC 2029 | C25: =IF(B25="","NÃO COMPRA","COMPRA") -> COMPRA | D25: =IFERROR(VLOOKUP(A25,Pedido!$A:$C,3,0),0) -> 4 | E25: =IFERROR(VLOOKUP(A25,Pedido!$A:$E,5,0),0) -> 453.6 | F25: A | G25: CILINDRO MESTRE DE EMBREAGEM RENAULT | H25: CILINDRO MESTRE DE EMBREAGEM | I25: RENAULT | J25: 306107623R (RENAULT) | K25: 2843 | L25: 0.21387384 | M25: =SUMIF(Relatorio_AK!$A:$A,A25,Relatorio_AK!$B:$B) -> 2843 | N25: =IF(M25=K25,"OK","DIF") -> OK | O25: =IFERROR(VLOOKUP($A25,Lista_Starke!$A:$E,3,0),"NÃO ESTÁ NA LISTA") -> RENAULT: Duster 1.6 16V 12/... RENAULT: Duster 2.0 16V F4R830 12/... | P25: =IFERROR(VLOOKUP($A25,Lista_Starke!$A:$E,2,0),"NÃO ESTÁ NA LISTA") -> CILINDRO MESTRE DE EMBREAGEM
A26: SBC1097 | B26: =IFERROR(VLOOKUP(A26,Pedido!$A:$B,2,0),"") | C26: =IF(B26="","NÃO COMPRA","COMPRA") -> NÃO COMPRA | D26: =IFERROR(VLOOKUP(A26,Pedido!$A:$C,3,0),0) -> 0 | E26: =IFERROR(VLOOKUP(A26,Pedido!$A:$E,5,0),0) -> 0 | F26: A | G26: CILINDRO MESTRE DE FREIO RENAULT | H26: CILINDRO MESTRE DE FREIO | I26: RENAULT | J26: 460114036R (OEM) | 6371 (ATE) | 6966 (ATE) | C2204 (CONTROIL) | K26: 2757 | L26: 0.21858701 | M26: =SUMIF(Relatorio_AK!$A:$A,A26,Relatorio_AK!$B:$B) -> 2757 | N26: =IF(M26=K26,"OK","DIF") -> OK | O26: =IFERROR(VLOOKUP($A26,Lista_Starke!$A:$E,3,0),"NÃO ESTÁ NA LISTA") -> RENAULT: Logan 1.0 / 1.6 07/11 RENAULT: Logan 1.0 / 1.6 12/... RENAULT: Sandero 1.0 / 1.6 07/11 RENAULT: Sandero 1.0 / 1.6 12/... | P26: =IFERROR(VLOOKUP($A26,Lista_Starke!$A:$E,2,0),"NÃO ESTÁ NA LISTA") -> CILINDRO MESTRE DE FREIO
A27: SBC1027 | B27: =IFERROR(VLOOKUP(A27,Pedido!$A:$B,2,0),"") | C27: =IF(B27="","NÃO COMPRA","COMPRA") -> NÃO COMPRA | D27: =IFERROR(VLOOKUP(A27,Pedido!$A:$C,3,0),0) -> 0 | E27: =IFERROR(VLOOKUP(A27,Pedido!$A:$E,5,0),0) -> 0 | F27: A | G27: CILINDRO MESTRE DE FREIO FORD | H27: CILINDRO MESTRE DE FREIO | I27: FORD | J27: C2061 (CONTROIL) | RCCD00910 (TRW) | K27: 2683 | L27: 0.22317367 | M27: =SUMIF(Relatorio_AK!$A:$A,A27,Relatorio_AK!$B:$B) -> 2683 | N27: =IF(M27=K27,"OK","DIF") -> OK | O27: =IFERROR(VLOOKUP($A27,Lista_Starke!$A:$E,3,0),"NÃO ESTÁ NA LISTA") -> FORD: Fiesta 1.0 / 1.3 96/02 FORD: Fiesta 1.0 01/07 FORD: Ka 1.0 08/13 | P27: =IFERROR(VLOOKUP($A27,Lista_Starke!$A:$E,2,0),"NÃO ESTÁ NA LISTA") -> CILINDRO MESTRE DE FREIO
A28: SWC5032 | B28: =IFERROR(VLOOKUP(A28,Pedido!$A:$B,2,0),"") | C28: =IF(B28="","NÃO COMPRA","COMPRA") -> NÃO COMPRA | D28: =IFERROR(VLOOKUP(A28,Pedido!$A:$C,3,0),0) -> 0 | E28: =IFERROR(VLOOKUP(A28,Pedido!$A:$E,5,0),0) -> 0 | F28: A | G28: CILINDRO DE RODA LE/LD FIAT | H28: CILINDRO DE RODA | I28: FIAT | J28: 0986AB8658 (BOSCH) | 5684 (ATE) | 71737949 (OEM) | 71737950 (OEM) | 7729634 (OEM) | 7757604 (OEM) | C3411 (CONTROIL) | CCR9230 (FORTEC) | CR1687 (BOSCH) | RCCR02120 (TRW) | K28: 2549 | L28: 0.22753125 | M28: =SUMIF(Relatorio_AK!$A:$A,A28,Relatorio_AK!$B:$B) -> 2549 | N28: =IF(M28=K28,"OK","DIF") -> OK | O28: =IFERROR(VLOOKUP($A28,Lista_Starke!$A:$E,3,0),"NÃO ESTÁ NA LISTA") -> FIAT: Brava 1.8 16V 99/07 FIAT: Doblo 1.3 16V / 1.6 16V 02/... FIAT: Doblo 1.8 16V 14/... FIAT: Doblo 1.8 8V 08/... FIAT: Fiorino 1.0 8V FIASA 94/95 FIAT: Fiorino 1.5 8V Sevel 88/93 FIAT: Idea 1.4 8V 06/12 FIAT: Idea 1.6 16V Etorq 11/16 FIAT: Idea 1.8 16V Etorq 11/16 FIAT: Idea 1.8 8V Powertrain 09/10 FIAT: Marea / Marea Weekend 2.0 20V / 2.4 20V 99/07 FIAT: Palio Weekend 1.4 8V 08/... FIAT: Palio Weekend 1.4 8V 08/12 FIAT: Palio Weekend 1.6 16V Etorq 11/... FIAT: Palio Weekend 1.8 8V Powertrain 04/... FIAT: Stilo 1.8 16V 02/05 FIAT: Stilo 1.8 8V 02/... FIAT: Strada 1.3 8V 03/... FIAT: Strada 1.4 8V 08/... FIAT: Strada 1.4 8V 09/12 FIAT: Strada 1.6 16V 98/... FIAT: Strada 1.8 8V 08/... FIAT: Tempra 2.0 8V / 2.0 16V 94/98 | P28: =IFERROR(VLOOKUP($A28,Lista_Starke!$A:$E,2,0),"NÃO ESTÁ NA LISTA") -> CILINDRO DE RODA LE/LD
A29: SCC2073 | B29: =IFERROR(VLOOKUP(A29,Pedido!$A:$B,2,0),"") | C29: =IF(B29="","NÃO COMPRA","COMPRA") -> NÃO COMPRA | D29: =IFERROR(VLOOKUP(A29,Pedido!$A:$C,3,0),0) -> 0 | E29: =IFERROR(VLOOKUP(A29,Pedido!$A:$E,5,0),0) -> 0 | F29: A | G29: CILINDRO MESTRE DE EMBREAGEM RENAULT | H29: CILINDRO MESTRE DE EMBREAGEM | I29: RENAULT | K29: 2503 | L29: 0.2318102 | M29: =SUMIF(Relatorio_AK!$A:$A,A29,Relatorio_AK!$B:$B) -> 2503 | N29: =IF(M29=K29,"OK","DIF") -> OK | O29: =IFERROR(VLOOKUP($A29,Lista_Starke!$A:$E,3,0),"NÃO ESTÁ NA LISTA") -> RENAULT: Logan 1.0 12V B4D 17/... RENAULT: Logan 1.6 8V K7M 14/... RENAULT: Sandero 1.0 12V B4D 17/... RENAULT: Sandero 1.6 8V K7M 14/... | P29: =IFERROR(VLOOKUP($A29,Lista_Starke!$A:$E,2,0),"NÃO ESTÁ NA LISTA") -> CILINDRO MESTRE DE EMBREAGEM
A30: SBC1005 | B30: =IFERROR(VLOOKUP(A30,Pedido!$A:$B,2,0),"") | C30: =IF(B30="","NÃO COMPRA","COMPRA") -> NÃO COMPRA | D30: =IFERROR(VLOOKUP(A30,Pedido!$A:$C,3,0),0) -> 0 | E30: =IFERROR(VLOOKUP(A30,Pedido!$A:$E,5,0),0) -> 0 | F30: A | G30: CILINDRO MESTRE DE FREIO VW | H30: CILINDRO MESTRE DE FREIO | I30: VOLKSWAGEN | J30: 0986AB8602 (BOSCH) | 30561101513 (OEM) | 5849 (ATE) | C2000 (CONTROIL) | RCCD00680 (TRW) | K30: 2390 | L30: 0.23589597 | M30: =SUMIF(Relatorio_AK!$A:$A,A30,Relatorio_AK!$B:$B) -> 2390 | N30: =IF(M30=K30,"OK","DIF") -> OK | O30: =IFERROR(VLOOKUP($A30,Lista_Starke!$A:$E,3,0),"NÃO ESTÁ NA LISTA") -> VOLKSWAGEN: Gol G1 85/96 VOLKSWAGEN: Gol G2 1.0 / 1.6 / 1.8 95/01 VOLKSWAGEN: Gol G2 1.0 02/05 VOLKSWAGEN: Gol G3 1.0 / 1.6 / 1.8 00 VOLKSWAGEN: Parati G1 85/96 VOLKSWAGEN: Saveiro G1 85/97 VOLKSWAGEN: Voyage G1 85/96 | P30: =IFERROR(VLOOKUP($A30,Lista_Starke!$A:$E,2,0),"NÃO ESTÁ NA LISTA") -> CILINDRO MESTRE DE FREIO
A31: SBC1042 | B31: =IFERROR(VLOOKUP(A31,Pedido!$A:$B,2,0),"") | C31: =IF(B31="","NÃO COMPRA","COMPRA") -> NÃO COMPRA | D31: =IFERROR(VLOOKUP(A31,Pedido!$A:$C,3,0),0) -> 0 | E31: =IFERROR(VLOOKUP(A31,Pedido!$A:$E,5,0),0) -> 0 | F31: A | G31: CILINDRO MESTRE DE FREIO GM | H31: CILINDRO MESTRE DE FREIO | I31: GM | K31: 2389 | L31: 0.23998003 | M31: =SUMIF(Relatorio_AK!$A:$A,A31,Relatorio_AK!$B:$B) -> 2389 | N31: =IF(M31=K31,"OK","DIF") -> OK | O31: =IFERROR(VLOOKUP($A31,Lista_Starke!$A:$E,3,0),"NÃO ESTÁ NA LISTA") -> GM: Cobalt 1.8 8V 13/... GM: Cobalt 1.8 8V 17/... GM: Onix 1.0 8V / 1.4 8V 13/... GM: Onix 1.0 8V / 1.4 8V 17/... GM: Prisma 1.0 8V / 1.4 8V 13/... GM: Prisma 1.0 8V / 1.4 8V 17/... | P31: =IFERROR(VLOOKUP($A31,Lista_Starke!$A:$E,2,0),"NÃO ESTÁ NA LISTA") -> CILINDRO MESTRE DE FREIO
A32: SWC5011 | B32: =IFERROR(VLOOKUP(A32,Pedido!$A:$B,2,0),"") | C32: =IF(B32="","NÃO COMPRA","COMPRA") -> NÃO COMPRA | D32: =IFERROR(VLOOKUP(A32,Pedido!$A:$C,3,0),0) -> 0 | E32: =IFERROR(VLOOKUP(A32,Pedido!$A:$E,5,0),0) -> 0 | F32: A | G32: CILINDRO DE RODA LE/LD GM | H32: CILINDRO DE RODA | I32: GM | J32: 0986AB8656 (BOSCH) | 95018639 (OEM) | 95231320 (OEM) | BWD6000 (TRW) | C3426 (CONTROIL) | CCR92267 (FORTEC) | K32: 2282 | L32: 0.24388117 | M32: =SUMIF(Relatorio_AK!$A:$A,A32,Relatorio_AK!$B:$B) -> 2282 | N32: =IF(M32=K32,"OK","DIF") -> OK | O32: =IFERROR(VLOOKUP($A32,Lista_Starke!$A:$E,3,0),"NÃO ESTÁ NA LISTA") -> GM: Cobalt 1.8 8V 13/... GM: Cobalt 1.8 8V 17/... GM: Onix 1.0 8V / 1.4 8V 13/... GM: Onix 1.0 8V / 1.4 8V 17/... GM: Prisma 1.0 8V / 1.4 8V 13/... GM: Prisma 1.0 8V / 1.4 8V 17/... GM: Sonic 1.6 16V 12/14 | P32: =IFERROR(VLOOKUP($A32,Lista_Starke!$A:$E,2,0),"NÃO ESTÁ NA LISTA") -> CILINDRO DE RODA LE/LD
A33: SSC3024 | B33: =IFERROR(VLOOKUP(A33,Pedido!$A:$B,2,0),"") | C33: =IF(B33="","NÃO COMPRA","COMPRA") -> NÃO COMPRA | D33: =IFERROR(VLOOKUP(A33,Pedido!$A:$C,3,0),0) -> 0 | E33: =IFERROR(VLOOKUP(A33,Pedido!$A:$E,5,0),0) -> 0 | F33: A | G33: CILINDRO AUXILIAR DE EMBREAGEM JAC | H33: CILINDRO AUXILIAR DE EMBREAGEM | I33: JAC MOTORS | K33: 2255 | L33: 0.24773616 | M33: =SUMIF(Relatorio_AK!$A:$A,A33,Relatorio_AK!$B:$B) -> 2255 | N33: =IF(M33=K33,"OK","DIF") -> OK | O33: =IFERROR(VLOOKUP($A33,Lista_Starke!$A:$E,3,0),"NÃO ESTÁ NA LISTA") -> JAC MOTORS: J2 1.4 16V 11/... JAC MOTORS: J3 1.4 16V 11/... JAC MOTORS: J5 1.4 16V 11/... | P33: =IFERROR(VLOOKUP($A33,Lista_Starke!$A:$E,2,0),"NÃO ESTÁ NA LISTA") -> CILINDRO AUXILIAR DE EMBREAGEM
A34: SCC2083 | B34: =IFERROR(VLOOKUP(A34,Pedido!$A:$B,2,0),"") | C34: =IF(B34="","NÃO COMPRA","COMPRA") -> NÃO COMPRA | D34: =IFERROR(VLOOKUP(A34,Pedido!$A:$C,3,0),0) -> 0 | E34: =IFERROR(VLOOKUP(A34,Pedido!$A:$E,5,0),0) -> 0 | F34: A | G34: CILINDRO MESTRE DE EMBREAGEM GM | H34: CILINDRO MESTRE DE EMBREAGEM | I34: GM | K34: 2204 | L34: 0.25150396 | M34: =SUMIF(Relatorio_AK!$A:$A,A34,Relatorio_AK!$B:$B) -> 2204 | N34: =IF(M34=K34,"OK","DIF") -> OK | O34: =IFERROR(VLOOKUP($A34,Lista_Starke!$A:$E,3,0),"NÃO ESTÁ NA LISTA") -> GM: Onix 1.0 12V 3 cil Aspirado 20/... GM: Onix 1.0 12V 3 cil Turbo 20/... GM: Tracker 1.0 12V 3 cil Turbo 20/... GM: Tracker 1.2 12V 3 cil Turbo 20/... | P34: =IFERROR(VLOOKUP($A34,Lista_Starke!$A:$E,2,0),"NÃO ESTÁ NA LISTA") -> CILINDRO MESTRE DE EMBREAGEM
A35: SWC5013 | B35: =IFERROR(VLOOKUP(A35,Pedido!$A:$B,2,0),"") -> SWC 5013 | C35: =IF(B35="","NÃO COMPRA","COMPRA") -> COMPRA | D35: =IFERROR(VLOOKUP(A35,Pedido!$A:$C,3,0),0) -> 20 | E35: =IFERROR(VLOOKUP(A35,Pedido!$A:$E,5,0),0) -> 637.6 | F35: A | G35: CILINDRO DE RODA LE/LD FIAT | H35: CILINDRO DE RODA | I35: FIAT | J35: 6987 (ATE) | 7088827 (OEM) | C3429 (CONTROIL) | CCR92283 (FORTEC) | K35: 2162 | L35: 0.25519995 | M35: =SUMIF(Relatorio_AK!$A:$A,A35,Relatorio_AK!$B:$B) -> 2162 | N35: =IF(M35=K35,"OK","DIF") -> OK | O35: =IFERROR(VLOOKUP($A35,Lista_Starke!$A:$E,3,0),"NÃO ESTÁ NA LISTA") -> FIAT: Argo 1.0 6V 3cil / 1.3 8V / 1.8 16V 17/... FIAT: Grand Siena 1.4 8V / 1.6 16V 12/... FIAT: Palio 1.0 8V / 1.4 8V / 1.6 16V 12/... FIAT: Uno 1.0 8V 11/... | P35: =IFERROR(VLOOKUP($A35,Lista_Starke!$A:$E,2,0),"NÃO ESTÁ NA LISTA") -> CILINDRO DE RODA LE/LD
A36: SBC1099 | B36: =IFERROR(VLOOKUP(A36,Pedido!$A:$B,2,0),"") | C36: =IF(B36="","NÃO COMPRA","COMPRA") -> NÃO COMPRA | D36: =IFERROR(VLOOKUP(A36,Pedido!$A:$C,3,0),0) -> 0 | E36: =IFERROR(VLOOKUP(A36,Pedido!$A:$E,5,0),0) -> 0 | F36: A | G36: CILINDRO MESTRE DE FREIO GM | H36: CILINDRO MESTRE DE FREIO | I36: GM | J36: 0986AB8570 (BOSCH) | 6476 (ATE) | 94735981 (OEM) | C-2174 (CONTROIL) | PMF6000 (TRW) | K36: 2119 | L36: 0.25882244 | M36: =SUMIF(Relatorio_AK!$A:$A,A36,Relatorio_AK!$B:$B) -> 2119 | N36: =IF(M36=K36,"OK","DIF") -> OK | O36: =IFERROR(VLOOKUP($A36,Lista_Starke!$A:$E,3,0),"NÃO ESTÁ NA LISTA") -> GM: Agile 1.4 11/... GM: Corsa Classic 1.0 08/... GM: Montana 1.4 11/13 | P36: =IFERROR(VLOOKUP($A36,Lista_Starke!$A:$E,2,0),"NÃO ESTÁ NA LISTA") -> CILINDRO MESTRE DE FREIO
A37: SCC2058 | B37: =IFERROR(VLOOKUP(A37,Pedido!$A:$B,2,0),"") | C37: =IF(B37="","NÃO COMPRA","COMPRA") -> NÃO COMPRA | D37: =IFERROR(VLOOKUP(A37,Pedido!$A:$C,3,0),0) -> 0 | E37: =IFERROR(VLOOKUP(A37,Pedido!$A:$E,5,0),0) -> 0 | F37: A | G37: CILINDRO MESTRE DE EMBREAGEM RENAULT | H37: CILINDRO MESTRE DE EMBREAGEM | I37: RENAULT | J37: 6001548446 (RENAULT) | 8200424004 (RENAULT) | 8200424007 (RENAULT) | K37: 2113 | L37: 0.26243467 | M37: =SUMIF(Relatorio_AK!$A:$A,A37,Relatorio_AK!$B:$B) -> 2113 | N37: =IF(M37=K37,"OK","DIF") -> OK | O37: =IFERROR(VLOOKUP($A37,Lista_Starke!$A:$E,3,0),"NÃO ESTÁ NA LISTA") -> RENAULT: Duster 1.6 16V 13/15 RENAULT: Duster 2.0 16V 13/15 | P37: =IFERROR(VLOOKUP($A37,Lista_Starke!$A:$E,2,0),"NÃO ESTÁ NA LISTA") -> CILINDRO MESTRE DE EMBREAGEM
A38: SOC9000 | B38: =IFERROR(VLOOKUP(A38,Pedido!$A:$B,2,0),"") | C38: =IF(B38="","NÃO COMPRA","COMPRA") -> NÃO COMPRA | D38: =IFERROR(VLOOKUP(A38,Pedido!$A:$C,3,0),0) -> 0 | E38: =IFERROR(VLOOKUP(A38,Pedido!$A:$E,5,0),0) -> 0 | F38: A | G38: RESFRIADOR OLEO FIAT | H38: RESFRIADOR DE ÓLEO CÂMBIO | I38: BMW / FIAT / JEEP / MINI | J38: 7089720 (OEM) | K38: 2094 | L38: 0.26601442 | M38: =SUMIF(Relatorio_AK!$A:$A,A38,Relatorio_AK!$B:$B) -> 2094 | N38: =IF(M38=K38,"OK","DIF") -> OK | O38: =IFERROR(VLOOKUP($A38,Lista_Starke!$A:$E,3,0),"NÃO ESTÁ NA LISTA") -> BMW: X1 2.0 16V 14/17 BMW: X2 1.5 12V 17/19 BMW: X2 2.0 16V 18/19 FIAT: Argo 1.3 8V 18/... FIAT: Argo 1.8 16V 17/... FIAT: Cronos 1.3 8V 18/... FIAT: Cronos 1.8 16V 18/... FIAT: Fastback 1.3 16V Turbo 23/... FIAT: Pulse 1.3 16V Turbo 22/... FIAT: Toro 1.3 16V Turbo 21/... FIAT: Toro 1.8 16V 16/... FIAT: Toro 2.0 16V Diesel 16/... FIAT: Toro 2.4 16V 16/... JEEP: Commander 1.3 16V Turbo 22/... JEEP: Compass 1.3 16V Turbo 21/... JEEP: Renegade 1.3 16V Turbo 21/... JEEP: Renegade 1.8 16V 15/... JEEP: Renegade 2.0 16V Diesel 16/... MINI: Clubman 2.0 16V 14/19 MINI: Cooper 1.2 12V / 1.5 12V / 2.0 16V 13/19 MINI: Countryman 1.5 12V / 2.0 16V 17/21 | P38: =IFERROR(VLOOKUP($A38,Lista_Starke!$A:$E,2,0),"NÃO ESTÁ NA LISTA") -> RESFRIADOR DE ÓLEO CÂMBIO
A39: SBS8000 | B39: =IFERROR(VLOOKUP(A39,Pedido!$A:$B,2,0),"") | C39: =IF(B39="","NÃO COMPRA","COMPRA") -> NÃO COMPRA | D39: =IFERROR(VLOOKUP(A39,Pedido!$A:$C,3,0),0) -> 0 | E39: =IFERROR(VLOOKUP(A39,Pedido!$A:$E,5,0),0) -> 0 | F39: A | G39: SAPATA DE FREIO FIAT | H39: SAPATA DE FREIO | I39: FIAT | J39: 0504CPA (COBREQ) | 203001 (SYL) | BPSA0090138 (MAZZICAR) | FI97CP (FRAS-LE) | HQJ502 (JURID) | K39: 2065 | L39: 0.2695446 | M39: =SUMIF(Relatorio_AK!$A:$A,A39,Relatorio_AK!$B:$B) -> 2065 | N39: =IF(M39=K39,"OK","DIF") -> OK | O39: =IFERROR(VLOOKUP($A39,Lista_Starke!$A:$E,3,0),"NÃO ESTÁ NA LISTA") -> FIAT: Mobi 1.0 12V 16/18 FIAT: Palio 1.0 / 1.3 / 1.5 / 1.6 96/03 FIAT: Palio 1.0 / 1.6 12/... FIAT: Palio 1.4 09/10 FIAT: Palio 1.8 8V 03/04 FIAT: Palio 1.8 8V 09/10 FIAT: Siena 1.0 / 1.4 13/... FIAT: Siena 1.0 / 1.6 96/03 FIAT: Uno 1.0 10/... FIAT: Uno 1.0 Economy 09/... FIAT: Uno 1.0 Fire 08/... | P39: =IFERROR(VLOOKUP($A39,Lista_Starke!$A:$E,2,0),"NÃO ESTÁ NA LISTA") -> SAPATA DE FREIO
A40: SBC1117 | B40: =IFERROR(VLOOKUP(A40,Pedido!$A:$B,2,0),"") -> SBC 1117 | C40: =IF(B40="","NÃO COMPRA","COMPRA") -> COMPRA | D40: =IFERROR(VLOOKUP(A40,Pedido!$A:$C,3,0),0) -> 6 | E40: =IFERROR(VLOOKUP(A40,Pedido!$A:$E,5,0),0) -> 679.14 | F40: A | G40: CILINDRO MESTRE DE FREIO GM | H40: CILINDRO MESTRE DE FREIO | I40: GM | J40: 6953 (ATE) | 94766501 (OEM) | C2221 (CONTROIL) | K40: 2053 | L40: 0.27305426 | M40: =SUMIF(Relatorio_AK!$A:$A,A40,Relatorio_AK!$B:$B) -> 2053 | N40: =IF(M40=K40,"OK","DIF") -> OK | O40: =IFERROR(VLOOKUP($A40,Lista_Starke!$A:$E,3,0),"NÃO ESTÁ NA LISTA") -> GM: Montana 1.4 8V 12/... | P40: =IFERROR(VLOOKUP($A40,Lista_Starke!$A:$E,2,0),"NÃO ESTÁ NA LISTA") -> CILINDRO MESTRE DE FREIO
...

Sheet Pedido
A1: Código (sem espaço) | B1: Código no pedido | C1: Quantidade | D1: Preço Liq | E1: Total
A2: SBC1011 | B2: SBC 1011 | C2: 4 | D2: 88 | E2: =C2*D2 -> 352
A3: SBC1117 | B3: SBC 1117 | C3: 6 | D3: 113.19 | E3: =C3*D3 -> 679.14
A4: SBC1124 | B4: SBC 1124 | C4: 6 | D4: 220 | E4: =C4*D4 -> 1320
A5: SBC1147 | B5: SBC 1147 | C5: 4 | D5: 242 | E5: =C5*D5 -> 968
A6: SBC1148 | B6: SBC 1148 | C6: 6 | D6: 195.63 | E6: =C6*D6 -> 1173.78
A7: SBC1149 | B7: SBC 1149 | C7: 6 | D7: 143.99 | E7: =C7*D7 -> 863.94
A8: SBC1188 | B8: SBC 1188 | C8: 8 | D8: 266.75 | E8: =C8*D8 -> 2134
A9: SCA8053FL | B9: SCA 8053 FL | C9: 3 | D9: 150 | E9: =C9*D9 -> 450
A10: SCA8053FR | B10: SCA 8053 FR | C10: 3 | D10: 150 | E10: =C10*D10 -> 450
A11: SCA8060FL | B11: SCA 8060 FL | C11: 3 | D11: 198 | E11: =C11*D11 -> 594
A12: SCA8060FR | B12: SCA 8060 FR | C12: 3 | D12: 198 | E12: =C12*D12 -> 594
A13: SCC2010 | B13: SCC 2010 | C13: 8 | D13: 62 | E13: =C13*D13 -> 496
... A26: SCC2003 | B26: SCC 2003 | C26: 10 | D26: 86.49 | E26: =C26*D26 -> 864.9

Sheet Relatorio_AK
A1: Código | B1: AK
A2: SSC3020 | B2: 9169
A3: SCC2064 | B3: 8838
A4: SBC1001 | B4: 4924
A5: SBC1087 | B5: 3768
A6: SBC1068 | B6: 3485
A7: SBC1000 | B7: 3454
A8: SBC1135 | B8: 3315
A9: SBC1090A | B9: 2941
A10: SBC1007 | B10: 2731
A11: SBC1014 | B11: 2656
A12: SBC1011 | B12: 2620
A13: SBC1085 | B13: 2617
... A2653: SFC7033 | B2653: 1

Sheet Lista_Starke
A1: Código (sem espaço) | B1: Produto | C1: Aplicação | D1: Conversões | E1: Observações
A2: SBB13000 | B2: SERVO FREIO | C2: FORD: Ka 1.0 8V Endura 97/99 FORD: Ka 1.0 8V Zetec Rocam 99/07 FORD: Ka 1.3 8V Endura 97/99 | D2: 1035528 (OEM) 97KB2005AA (OEM) 97KB2005AB (OEM) 97KB2005AE (OEM) 97KU2005AA (OEM) 97KU2005AB (OEM) C5638 (CONTROIL) RCSF00970 (TRW) | E2: Ø 200,00 mm Sistema ATE
A3: SBB13001 | B3: SERVO FREIO | C3: GM: Cobalt 1.4 8V 17/... GM: Cobalt 1.8 8V 15/... GM: Onix 1.0 12V 3 cil. Aspirado 19/... GM: Onix 1.0 12V 3 cil. Turbo 19/... GM: Onix 1.0 8V 12/16 GM: Onix 1.4 8V 12/16 GM: Onix 1.4 8V 16/... GM: Prisma 1.4 8V 13/16 | D3: 52019450 (OEM) C5677 (CONTROIL) | E3: Ø 230,00 mm
A4: SBB13002 | B4: SERVO FREIO | C4: GM: Onix 1.0 12V 3 cil. Turbo 19/... GM: Tracker 1.0 12V 3 cil. Turbo 20/... | D4: 897001582 (OEM) C5683 (CONTROIL) | E4: Ø 230,00 mm
A5: SBB13005 | B5: SERVO FREIO | C5: GM: Chevette 1.0 8V 92/93 GM: Chevette 1.6 8V 87/94 GM: Chevy 1.6 8V 87/92 GM: Marajo 1.6 8V 87/90 | D5: 5420 (ATE) 5798 (ATE) 94656135 (OEM) C5616 (CONTROIL) | E5: Ø 200,00 mm Sistem Varga
A6: SBB13006 | B6: SERVO FREIO | C6: VOLKSWAGEN: Gol 1.0 16V Turbo 00/01 VOLKSWAGEN: Parati 1.0 16V Turbo 00/01 | D6: C5665 (CONTROIL) SF2623 (BOSCH) | E6: Ø 230,00
A7: SBB13007 | B7: SERVO FREIO | C7: SEAT: Cordoba 1.6 8V 99/00 SEAT: Cordoba 1.8 8V 94/02 SEAT: Ibiza 1.0 16V 99/02 SEAT: Ibiza 1.6 8V 99/02 SEAT: Ibiza 1.8 8V 94/99 SEAT: Inca 1.6 8V 99/02 VOLKSWAGEN: Polo Classic 1.8 8V 96/03 VOLKSWAGEN: Van 1.6 8V 98/03 | D7: 204125262 (BOSCH) 6K161207F (OEM) 6K161207G (OEM) 6K1612107G (OEM) C5643 (CONTROIL) | E7: Ø 230,00 mm
A8: SBB13008 | B8: SERVO FREIO | C8: GM: Ipanema 1.8 8V Sist. ATE 91/97 GM: Ipanema 2.0 8V Sist. ATE 91/97 GM: Ipanema 2.0 8V Sist. Bosch 91/97 GM: Kadett 1.8 8V Sist. Varga 89/97 GM: Kadett 2.0 8V Sist. Varga 91/97 | D8: 52256123 (OEM) 52286809 (OEM) 6436 (ATE) C5614 (CONTROIL) NKF10014 (NAKATA) RCSF00611 (TRW) SF3956 (BOSCH) | E8: Ø 200,00 mm
A9: SBB13010 | B9: SERVO FREIO | C9: HONDA: HRV 1.5 16V Turbo 19/... HONDA: HRV 1.8 16V 15/22 | D9: C5686 (CONTROIL) NM230V74 (OEM) | E9: Ø 230,00 mm
A10: SBB13011 | B10: SERVO FREIO | C10: GM: Chevette 1.4 8V 77/86 GM: Chevette 1.6 8V 82/86 GM: Chevy 1.6 8V 83/86 GM: Marajo 1.6 8V 82/86 | D10: 2252624 (OEM) 2253417 (OEM) 94622158 (OEM) C5602 (CONTROIL) SF3417 (BOSCH) | E10: Ø 216,00 mm
A11: SBB13012 | B11: SERVO FREIO | C11: AGRALE: 1600 A 2.5 L 8V SOHC L4 Sist. Varga 86/89 AGRALE: 1600 D SERIE 229 3.0 L 6V SOHV L3 Sist. Varga 86/89 AGRALE: 1600 D SERIE 229 3.9 L 8V SOHV L4 Sist. ATE 86/89 AGRALE: 1800 D Q20B 3.9 L 8V SOHV L4 Sist. ATE 88/89 AGRALE: 1800 D SERIE 229 3.9 L 8V SOHV L4 Sist. ATE 88/89 GM: A10 4.1 12V 6 cil. Sist. ATE 85/88 GM: A20 4.1 12V 6 cil. Sist. ATE 85/88 GM: A20 4.1 12V 6 cil. Sist. Varga 85/88 GM: C20 4.1 12V 6 cil. Sist. Varga 85/89 | D11: 6442 (ATE) 94632228 (OEM) C5621 (CONTROIL) RCSF00060 (TRW) SF3646 (BOSCH) | E11: Ø 200,00 mm
A12: SBB13013 | B12: SERVO FREIO | C12: FORD: Ka 1.0 8V Zetec Rocam 01/07 FORD: Ka 1.6 8V Zetec Rocam 01/07 | D12: 7893049567138 (OEM) C5671 (CONTROIL) | E12: Ø 200,00 mm
... A20: SBB13026 | B20: SERVO FREIO | C20: MITSUBISHI: L200 2.5 8V 4D56 94/96 MITSUBISHI: L200 2.5 8V 4D56 97/03 MITSUBISHI: L200 Sport 2.5 8V 4D56 97/03 | D20: C5663 (CONTROIL) MB618976 (OEM) | E20: Ø 230,00 mm
A21: SBB13027 | B21: SERVO FREIO | C21: GM: Corsa Sedan / Wagon 1.6 16V 97/98 | D21: 5938 (ATE) 93272823 (OEM) C5647 (CONTROIL)
A22: SBB13028 | B22: SERVO FREIO | C22: VOLKSWAGEN: Santana 2.0 8V AP 94/06 | D22: 2265406S (OEM) C5652 (CONTROIL) SF5406S (BOSCH) | E22: Ø 230,00 mm Modelos com ABS
A23: SBB13029 | B23: SERVO FREIO | C23: FORD: Escort 1.6 8V AP Sist. Varga 94/96 FORD: Escort 1.8 8V AP Sist. Varga 94/96 FORD: Escort 2.0 8V AP Sist. ATE/Bosch 94/96 FORD: Escort XR/XR3 2.0 8V AP Sist. Varga 94/96 FORD: Verona 1.8 8V AP Sist. ATE/Bosch 94/96 FORD: Verona 2.0 8V AP Sist. ATE/Bosch 94/96 VOLKSWAGEN: Logus 1.6 8V AP Sist. ATE/Bosch 94/96 VOLKSWAGEN: Logus 1.8 8V AP Sist. ATE/Bosch 94/96 VOLKSWAGEN: Logus 2.0 8V AP Sist. ATE/Bosch 94/96 VOLKSWAGEN: Pointer 1.8 8V AP Sist. ATE/Bosch 94/96 VOLKSWAGEN: Pointer 2.0 8V AP Sist. ATE/Bosch 94/96 VOLKSWAGEN: Pointer GTI 2.0 8V AP Sist. ATE/Bosch 94/96 | D23: 547612907A (OEM) C5623 (CONTROIL) RCSF00816 (TRW) | E23: Ø 230,00 mm
A24: SBB13030 | B24: SERVO FREIO | C24: FIAT: Argo 1.0 6V 3 cil. Firefly 19/... FIAT: Argo 1.3 8V Firefly 17/... FIAT: Argo 1.8 16V Etorq 17/21 FIAT: Cronos 1.0 6V 3 cil. Firefly c/ ABS 22/... FIAT: Cronos 1.3 8V Firefly 18/22 FIAT: Cronos 1.3 8V Firefly 22/... FIAT: Cronos 1.8 16V Etorq 19/22 FIAT: Fiorino 1.4 8V Fire Evo 20/... FIAT: Fiorino 1.4 8V Fire Evo c/ ABS 13/20 FIAT: Fiorino 1.4 8V Fire Evo c/ ABS 16/20 FIAT: Grand Siena 1.4 8V Fire Evo c/ ABS 13/20 FIAT: Grand Siena 1.6 16V Etorq c/ ABS 13/18 FIAT: Mobi 1.0 8V Fire Evo c/ ABS 17/... FIAT: Palio 1.0 8V Fire 13/16 FIAT: Palio 1.4 8V Fire Evo 14/18 FIAT: Palio 1.6 16V Etorq 12/18 FIAT: Uno 1.0 6V 3 cil. Firefly c/ ABS 17/21 FIAT: Uno 1.0 8V Fire Evo c/ ABS 13/17 FIAT: Uno 1.3 8V Firefly 16/19 FIAT: Uno 1.4 8V Fire Evo c/ ABS 13/14 FIAT: Uno 1.4 8V Fire Evo c/ ABS 14/... FIAT: Uno 1.4 8V Fire Evo c/ ABS 14/16 FIAT: Uno Mille 10. 8V Fire c/ ABS 13/13 FIAT: Uno Way 1.0 6V 3 cil. Firefly c/ ABS 16/20 | D24: 51934114 (OEM) C5678 (CONTROIL) | E24: Ø 230,00 mm
A25: SBB13031 | B25: SERVO FREIO | C25: RENAULT: Logan 1.0 12V 3 cil. 19/... RENAULT: Logan 1.6 16V H4M 17/... RENAULT: Logan 1.6 8V K7M 15/... RENAULT: Sandero 1.0 12V 3 cil. 17/... RENAULT: Sandero 1.0 16V D4D 14/17 RENAULT: Sandero 1.6 16V H4M 17/19 RENAULT: Sandero 1.6 16V K7M 15/16 RENAULT: Sandero 1.6 8V K7M 16/17 | D25: 472103385R (OEM) C5687 (CONTROIL) | E25: Ø 230,00 mm
A26: SBB13032 | B26: SERVO FREIO | C26: RENAULT: Captur 1.6 16V SCE H4M 16/21 RENAULT: Captur 2.0 16V F4R 16/21 RENAULT: Duster 1.6 16V SCE H4M 11/21 RENAULT: Duster 2.0 16V F4R 11/21 RENAULT: Oroch 1.6 16V SCE H4M 16/21 RENAULT: Oroch 2.0 16V F4R 16/21 | D26: 472104244R (OEM) | E26: Sistema ATE
A27: SBB13033 | B27: SERVO FREIO | C27: PEUGEOT: 206 1.0 16V D4D 01/04 PEUGEOT: 206 1.4 8V TU3JP 05/09 PEUGEOT: 206 1.6 8V TU5JP4 99/01 PEUGEOT: 207 1.4 8V TU3JP 09/11 | D27: 204125605 (BOSCH) 4535J2 (OEM) 6065 (ATE) C5664 (CONTROIL) | E27: Ø 230,00 mm
A28: SBB13034 | B28: SERVO FREIO | C28: FIAT: Palio 1.0 8V Fire 03/11 FIAT: Palio 1.0 8V Fire 05/10 FIAT: Palio 1.3 16V 00/03 FIAT: Palio 1.3 8V Fire 02/03 FIAT: Palio 1.4 8V Fire 07/08 FIAT: Palio 1.4 8V Fire Evo 11/17 FIAT: Palio 1.6 16V Etorq 10/17 FIAT: Palio 1.8 8V Powertrain 03/10 FIAT: Palio Weekend 1.3 8V Fire 02/04 FIAT: Palio Weekend 1.4 8V Fire 08/... FIAT: Palio Weekend 1.6 16V Etorq 10/12 FIAT: Palio Weekend 1.8 8V Powertrain 03/04 FIAT: Palio Weekend Adventure Locker 1.8 16V Etorq 10/12 FIAT: Palio Weekend Adventure Locker 1.8 8V Powertrain 04/08 FIAT: Siena 1.0 16V Fire 00/03 FIAT: Siena 1.0 8V Fire 04/09 FIAT: Siena 1.0 8V Fire 06/10 FIAT: Siena 1.3 16V Fire 00/03 FIAT: Siena 1.4 8V Fire 07/12 FIAT: Siena 1.6 16V Etorq 10/12 FIAT: Siena 1.8 8V Powertrain 07/10 FIAT: Strada 1.3 8V Fire 02/05 FIAT: Strada 1.4 8V Fire 05/12 FIAT: Strada 1.8 16V Etorq 10/12 FIAT: Strada 1.8 8V Powertrain 05/10 | D28: 204032385 (BOSCH) 6027 (ATE) 6031 (ATE) 7081979 (OEM) 7082042 (OEM) C5656 (CONTROIL) SF2622 (BOSCH) | E28: Ø 230,00 mm
A29: SBB13035 | B29: SERVO FREIO | C29: GM: Astra 2.0 8V 95/96 GM: Vectra 2.0 8V 94/96 GM: Vectra GSI 2.0 16V 94/96 | D29: 3492871 (OEM) C5642 (CONTROIL) | E29: Ø 230,00 mm
A30: SBB13036 | B30: SERVO FREIO | C30: FIAT: Palio 1.0 8V FIASA Sist. ATE/Bosch 98/99 FIAT: Palio 1.5 8V FIASA Sust. ATE/Bosch 98/99 FIAT: Palio 1.6 8V SEVEL Sist. ATE/Bosch 98/99 FIAT: Palio Economy 1.5 8V FIASA Sist. ATE/Bosch 99/99 FIAT: Palio Weekend 1.0 8V FIASA Sist. ATE/Bosch 99/99 FIAT: Palio Weekend 1.6 8V SEVEL Sist. ATE/Bosch 99/99 FIAT: Siena 1.6 8V SEVEL Sist. ATE/Bosch 98/99 FIAT: Strada 1.5 8V SEVEL Sist. ATE/Bosch 99/99 FIAT: Strada 1.6 8V FIASA Sist. ATE/Bosch 99/99 | D30: 5922 (ATE) 5979 (ATE) 7079575 (OEM) 7081252 (OEM) C5636 (CONTROIL) SF9388 (BOSCH) | E30: Ø 230,00 mm
A31: SBB13037 | B31: SERVO FREIO | C31: FORD: Ecosport 1.6 8V Zetec Rocam c/ ABS 10/12 FORD: Ecosport 2.0 16V 4x4 Duratec c/ ABS 10/12 FORD: Ecosport 2.0 16V Duratec c/ ABS 10/12 FORD: Fiesta 1.0 8V Zetec Rocam c/ ABS 10/14 FORD: Fiesta 1.6 8V Zetec Rocam c/ ABS 10/14 | D31: 6938 (ATE) 6S652005AB (OEM) C5680 (CONTROIL) | E31: Ø 230,00 mm
A32: SBB13039 | B32: SERVO FREIO | C32: FORD: Courier 1.3 8V Endura Sist. ATE/Bosch 97/99 FORD: Courier 1.4 16V Zetec Sist. ATE/Bosch 97/99 FORD: Courier 1.6 8V Zetec Rocam Sist. ATE/Bosch 07/09 FORD: Courier 1.6 8V Zetec Rocam Sist. ATE/Bosch 99/07 FORD: Fiesta 1.0 8V Endura Sist. ATE/Bosch 96/99 FORD: Fiesta 1.0 8V Zetec Rocam Sist. ATE/Bosch 01/04 FORD: Fiesta 1.3 8V HCS Sist. ATE/Bosch 95/99 FORD: Fiesta 1.6 8V Zetec Rocam Sist. ATE/Bosch 99/05 FORD: Ka 1.6 8V Zetec Rocam Sist. ATE/Bosch 08/14 | D32: 6443 (ATE) 96FB2005EF (OEM) 97FU2005AA (OEM) 97FU2005AB (OEM) 986485129 (BOSCH) C5635 (CONTROIL) RCSF00960 (TRW) | E32: Ø 230,00 mm
A33: SBB13040 | B33: SERVO FREIO | C33: RENAULT: Clio 1.6 8V K7M 96/99 | D33: 204125153 (BOSCH) 7701204854 (OEM) 7701204857 (OEM) 7702217954 (OEM) C5655 (CONTROIL) | E33: Ø 200,00 mm
... A61: SBB13080 | B61: SERVO FREIO | C61: TOYOTA: Hilux 2.5 Turbo Diesel 2KD 05/15 TOYOTA: Hilux 3.0 Turbo Diesel 1KD 05/15 TOYOTA: SW4 3.0 Turbo Diesel 1KD 05/15 | D61: 44610-09290 (OEM) | E61: Apenas para modelos sem controle de estabilidade
A62: SBB13082 | B62: SERVO FREIO | C62: MITSUBISHI: L200 Outdoor 2.5 8V TD 08/11 MITSUBISHI: L200 Savana 2.5 8V TD 08/11 MITSUBISHI: L200 Sport 2.5 8V TD 03/07 | D62: MR449474 (OEM)
A63: SBB13083 | B63: SERVO FREIO | C63: MITSUBISHI: Pajero Dakar 3.2 16V Diesel 4M41 DI-D 07/13 MITSUBISHI: Pajero Full 3.2 16V Diesel 4M41 DI-D 07/13 MITSUBISHI: Triton 3.2 16V Diesel 4M41 DI-D 07/13 MITSUBISHI: Triton 3.5 V6 24V Flex 6G74 10/13 MITSUBISHI: Triton 3.5 V6 24V Gasolina 6G74 07/13 | D63: 4630A173 (OEM)
A64: SBB13084 | B64: SERVO FREIO | C64: GM: Blazer 2.2 EFI 95/98 GM: Blazer 2.2 MPFI 97/00 GM: Blazer 2.4 MPFI 00/12 GM: Blazer 2.5 Diesel 4x4 97/00 GM: Blazer 2.8 Diesel 00/12 GM: Blazer 4.3 V6 MPFI 96/03 GM: S10 2.2 EFI 95/97 GM: S10 2.2 MPFI 97/00 GM: S10 2.4 MPFI 00/12 GM: S10 2.8 Diesel 4x4 00/12 GM: S10 4.3 V6 96/03 TROLLER: T4 2.8 Turbo Diesel NGD 01/05 TROLLER: T4 3.0 Turbo Diesel NGD 99/... TROLLER: T4 3.2 20V Turbo Diesel 14/... | D64: 0204032381 (BOSCH) 0204032382 (BOSCH) 02040C2062 (BOSCH) 7908449963821 (OEM) SF2062 (BOSCH) SF5610S (BOSCH) | E64: Ø 205,00 mm
A65: SBB13088 | B65: SERVO FREIO | C65: FORD: Transit 2.2 16V Duratorq 08/14 FORD: Transit 2.4 16V Duratorq Puma 08/14 | D65: 0204125857 (BOSCH) 0204774973 (BOSCH) 0204774975 (BOSCH) 6C112005BE (OEM) SF4975 (BOSCH) | E65: Ø 431,00 MM
A66: SBB13089 | B66: SERVO FREIO | C66: NISSAN: Frontier 2.5 16V YD25DDTi 08/16 | D66: 0204844200 (BOSCH) 47210-JR80A (OEM) | E66: Ø 248,00 mm Apenas para modelos: 144cv 163cv 172cv
A67: SBB13113 | B67: SERVO FREIO | C67: GM: Classic 1.0 8V VHCE 08/10 | D67: 6475 (ATE) 94736008 (OEM) C5672 (CONTROIL) | E67: Ø 200,00 mm
A68: SBB13125 | B68: SERVO FREIO | C68: GM: Agile 1.4 8V 11/14 | D68: 6949 (ATE) 94757697 (OEM) | E68: Ø 225,00 MM C/ ABS Sistema ATE
A69: SBB13137 | B69: HIDROBOOSTER | C69: FORD: F250 4.2 16V Cummins 4BTAA 98/12 FORD: F250 4.2 16V MWM 6.07 TCA 98/12 FORD: F250 4.2 V6 Diesel 98/12 FORD: F250 Super Duty 3.9 16V Cummins 98/12 FORD: F250 Super Duty 4.2 V6 Diesel 98/12 FORD: F250 Tropical 4.2 18V MWM 6.07TCA 04/12 FORD: F250 Tropical 4.2 V6 Diesel 98/12 FORD: F350 3.9 16V Cummins 4BTAA 98/19 FORD: F350 3.9 8V Cummins 4bTAA 98/19 FORD: F4000 2.9 8V MWM 229/4 98/19 FORD: F4000 3.9 8V Cummins 4BTT 98/19 | D69: 1C3Z2005AA (OEM) 5C7Z2005B (OEM) 7C3Z2005A (OEM)
A70: SBB13139 | B70: SERVO FREIO | C70: MITSUBISHI: Pajero IO 1.8 16V 4G93 99/02 MITSUBISHI: Pajero TR4 2.0 16V 00/… MITSUBISHI: Pajero TR4 2.0 20V 4G94 04/… | D70: MR370642 (OEM)
A71: SBB13140 | B71: SERVO FREIO | C71: FORD: Edge 3.5 V6 11/14 | D71: BA1Z2005A (OEM)
A72: SBB13141 | B72: SERVO FREIO | C72: HONDA: New Civic 1.8 16V 07/11 HONDA: New Civic 1.8 16V 12/16 HONDA: New Civic 2.0 16V 13/16 | D72: 01469TR8M00 (OEM) | E72: Ø 240,00 mm
A73: SBB13142 | B73: SERVO FREIO | C73: HYUNDAI: HR 2.5 16V Diesel 13/22 KIA: Bongo K2500 2.5 16V Diesel 13/22 | D73: 586104F010 (OEM)
A74: SBB13143 | B74: SERVO FREIO | C74: MERCEDES-BENZ: Sprinter 311 2.2 CDI OM651 12/17 MERCEDES-BENZ: Sprinter 415 2.2 CDI OM651 12/19 MERCEDES-BENZ: Sprinter 515 2.2 CDI OM651 12/19 | D74: 9064301408 (OEM) A9064301408 (OEM) A9064301408Q9 (OEM)
...
