Workbook
Name Slicer_Classe: #N/A
Name Slicer_Familia: #N/A
Name Slicer_Montadora: #N/A

Sheet Planilha1
A1: CURVA ABC POR CÓDIGO
A2: Itens consolidados por código, ordenados pelo volume total do histórico.
A6: Código | B6: Produto | C6: Representada | D6: Total | E6: % Total | F6: % Acumulado | G6: Classe | H6: Familia | I6: Cross | J6: Montadora | K6: QTD COMPRADA - ESTHER DIST. | L6: COMPRA / NÃO COMPRA
A7: SSC3020 | B7: CILINDRO AUXILIAR DE EMBREAGEM HYUNDAI | C7: =VLOOKUP(A7,[2]Planilha1!$A:$B,2,0) -> #N/A | D7: =SUMIF([1]Relatório!$A$2:$A$2653,A7,[1]Relatório!$AK$2:$AK$2653) -> 15657 | E7: =D7/SUM($D$7:$D$1708) -> 0.02676607 | F7: =SUM($E$7:E7) -> 0.02676607 | G7: =IF(F7<=70%,"A",IF(F7<=90%,"B","C")) -> A | H7: CILINDRO AUXILIAR DE EMBREAGEM | J7: HYUNDAI | K7: =IFERROR(VLOOKUP(A7,'Pedido ESTHER'!$B:$C,2,0),"") | L7: =IF(N(K7)>0,"COMPRA","NÃO COMPRA") -> NÃO COMPRA
A8: SCC2064 | B8: CILINDRO MESTRE DE EMBREAGEM HYUNDAI | C8: =VLOOKUP(A8,[2]Planilha1!$A:$B,2,0) -> #N/A | D8: =SUMIF([1]Relatório!$A$2:$A$2653,A8,[1]Relatório!$AK$2:$AK$2653) -> 14311 | E8: =D8/SUM($D$7:$D$1708) -> 0.024465046 | F8: =SUM($E$7:E8) -> 0.051231116 | G8: =IF(F8<=70%,"A",IF(F8<=90%,"B","C")) -> A | H8: CILINDRO MESTRE DE EMBREAGEM | J8: HYUNDAI | K8: =IFERROR(VLOOKUP(A8,'Pedido ESTHER'!$B:$C,2,0),"") | L8: =IF(N(K8)>0,"COMPRA","NÃO COMPRA") -> NÃO COMPRA
A9: SBC1000 | B9: CILINDRO MESTRE DE FREIO VW | C9: =VLOOKUP(A9,[2]Planilha1!$A:$B,2,0) -> #N/A | D9: =SUMIF([1]Relatório!$A$2:$A$2653,A9,[1]Relatório!$AK$2:$AK$2653) -> 6588 | E9: =D9/SUM($D$7:$D$1708) -> 0.011262366 | F9: =SUM($E$7:E9) -> 0.062493482 | G9: =IF(F9<=70%,"A",IF(F9<=90%,"B","C")) -> A | H9: CILINDRO MESTRE DE FREIO | I9: 5109 (ATE) | C2003 (CONTROIL) | RCCM23314 (TRW) | J9: VOLKSWAGEN | K9: =IFERROR(VLOOKUP(A9,'Pedido ESTHER'!$B:$C,2,0),"") | L9: =IF(N(K9)>0,"COMPRA","NÃO COMPRA") -> NÃO COMPRA
A10: SBC1090A | B10: CILINDRO MESTRE FREIO VW | C10: =VLOOKUP(A10,[2]Planilha1!$A:$B,2,0) -> #N/A | D10: =SUMIF([1]Relatório!$A$2:$A$2653,A10,[1]Relatório!$AK$2:$AK$2653) -> 6193 | E10: =D10/SUM($D$7:$D$1708) -> 0.010587103 | F10: =SUM($E$7:E10) -> 0.073080585 | G10: =IF(F10<=70%,"A",IF(F10<=90%,"B","C")) -> A | H10: CILINDRO MESTRE DE FREIO | J10: VOLKSWAGEN | K10: =IFERROR(VLOOKUP(A10,'Pedido ESTHER'!$B:$C,2,0),"") | L10: =IF(N(K10)>0,"COMPRA","NÃO COMPRA") -> NÃO COMPRA
A11: SBC1001 | B11: CILINDRO MESTRE DE FREIO RENAULT | C11: =VLOOKUP(A11,[2]Planilha1!$A:$B,2,0) -> #N/A | D11: =SUMIF([1]Relatório!$A$2:$A$2653,A11,[1]Relatório!$AK$2:$AK$2653) -> 5930 | E11: =D11/SUM($D$7:$D$1708) -> 0.010137497 | F11: =SUM($E$7:E11) -> 0.083218083 | G11: =IF(F11<=70%,"A",IF(F11<=90%,"B","C")) -> A | H11: CILINDRO MESTRE DE FREIO | I11: 0986AB8673 (BOSCH) | 7701205740 (OEM) | 7701205815 (OEM) | C2096 (CONTROIL) | J11: RENAULT | K11: =IFERROR(VLOOKUP(A11,'Pedido ESTHER'!$B:$C,2,0),"") | L11: =IF(N(K11)>0,"COMPRA","NÃO COMPRA") -> NÃO COMPRA
A12: SBC1137 | B12: CILIDNRO MESTRE DE FREIO FIAT | C12: =VLOOKUP(A12,[2]Planilha1!$A:$B,2,0) -> #N/A | D12: =SUMIF([1]Relatório!$A$2:$A$2653,A12,[1]Relatório!$AK$2:$AK$2653) -> 5587 | E12: =D12/SUM($D$7:$D$1708) -> 0.0095511294 | F12: =SUM($E$7:E12) -> 0.092769212 | G12: =IF(F12<=70%,"A",IF(F12<=90%,"B","C")) -> A | H12: CILINDRO MESTRE DE FREIO | I12: 0204798525 (BOSCH) | J12: FIAT | K12: =IFERROR(VLOOKUP(A12,'Pedido ESTHER'!$B:$C,2,0),"") | L12: =IF(N(K12)>0,"COMPRA","NÃO COMPRA") -> NÃO COMPRA
A13: SCC2017 | B13: CILINDRO MESTRE DE EMBREAGEM HONDA | C13: =VLOOKUP(A13,[2]Planilha1!$A:$B,2,0) -> #N/A | D13: =SUMIF([1]Relatório!$A$2:$A$2653,A13,[1]Relatório!$AK$2:$AK$2653) -> 5428 | E13: =D13/SUM($D$7:$D$1708) -> 0.0092793145 | F13: =SUM($E$7:E13) -> 0.10204853 | G13: =IF(F13<=70%,"A",IF(F13<=90%,"B","C")) -> A | H13: CILINDRO MESTRE DE EMBREAGEM | J13: HONDA | K13: =IFERROR(VLOOKUP(A13,'Pedido ESTHER'!$B:$C,2,0),"") -> 1 | L13: =IF(N(K13)>0,"COMPRA","NÃO COMPRA") -> COMPRA
A14: SBC1068 | B14: CILINDRO MESTRE DE FREIO FORD | C14: =VLOOKUP(A14,[2]Planilha1!$A:$B,2,0) -> #N/A | D14: =SUMIF([1]Relatório!$A$2:$A$2653,A14,[1]Relatório!$AK$2:$AK$2653) -> 5372 | E14: =D14/SUM($D$7:$D$1708) -> 0.009183581 | F14: =SUM($E$7:E14) -> 0.11123211 | G14: =IF(F14<=70%,"A",IF(F14<=90%,"B","C")) -> A | H14: CILINDRO MESTRE DE FREIO | I14: 2S652140CA (OEM) | 6168 (ATE) | C2155 (CONTROIL) | J14: FORD | K14: =IFERROR(VLOOKUP(A14,'Pedido ESTHER'!$B:$C,2,0),"") | L14: =IF(N(K14)>0,"COMPRA","NÃO COMPRA") -> NÃO COMPRA
A15: SBC1123 | B15: CILINDRO MESTRE DE FREIO GM | C15: =VLOOKUP(A15,[2]Planilha1!$A:$B,2,0) -> #N/A | D15: =SUMIF([1]Relatório!$A$2:$A$2653,A15,[1]Relatório!$AK$2:$AK$2653) -> 4985 | E15: =D15/SUM($D$7:$D$1708) -> 0.0085219939 | F15: =SUM($E$7:E15) -> 0.1197541 | G15: =IF(F15<=70%,"A",IF(F15<=90%,"B","C")) -> A | H15: CILINDRO MESTRE DE FREIO | I15: 6989 (ATE) | 94756709 (OEM) | C2220 (CONTROIL) | J15: GM | K15: =IFERROR(VLOOKUP(A15,'Pedido ESTHER'!$B:$C,2,0),"") | L15: =IF(N(K15)>0,"COMPRA","NÃO COMPRA") -> NÃO COMPRA
A16: SBC1087 | B16: CILINDRO MESTRE DE FREIO RENAULT | C16: =VLOOKUP(A16,[2]Planilha1!$A:$B,2,0) -> #N/A | D16: =SUMIF([1]Relatório!$A$2:$A$2653,A16,[1]Relatório!$AK$2:$AK$2653) -> 4922 | E16: =D16/SUM($D$7:$D$1708) -> 0.0084142937 | F16: =SUM($E$7:E16) -> 0.1281684 | G16: =IF(F16<=70%,"A",IF(F16<=90%,"B","C")) -> A | H16: CILINDRO MESTRE DE FREIO | I16: 460118760R (OEM) | 6001551613 (OEM) | 6967 (ATE) | C-2178 (CONTROIL) | J16: RENAULT | K16: =IFERROR(VLOOKUP(A16,'Pedido ESTHER'!$B:$C,2,0),"") | L16: =IF(N(K16)>0,"COMPRA","NÃO COMPRA") -> NÃO COMPRA
A17: SCC2060 | B17: CILINDRO MESTRE DE EMBREAGEM RENAULT | C17: =VLOOKUP(A17,[2]Planilha1!$A:$B,2,0) -> #N/A | D17: =SUMIF([1]Relatório!$A$2:$A$2653,A17,[1]Relatório!$AK$2:$AK$2653) -> 4719 | E17: =D17/SUM($D$7:$D$1708) -> 0.0080672596 | F17: =SUM($E$7:E17) -> 0.13623565 | G17: =IF(F17<=70%,"A",IF(F17<=90%,"B","C")) -> A | H17: CILINDRO MESTRE DE EMBREAGEM | J17: NISSAN / RENAULT | K17: =IFERROR(VLOOKUP(A17,'Pedido ESTHER'!$B:$C,2,0),"") | L17: =IF(N(K17)>0,"COMPRA","NÃO COMPRA") -> NÃO COMPRA
A18: SBC1014 | B18: CILINDRO MESTRE DE FREIO FIAT | C18: =VLOOKUP(A18,[2]Planilha1!$A:$B,2,0) -> #N/A | D18: =SUMIF([1]Relatório!$A$2:$A$2653,A18,[1]Relatório!$AK$2:$AK$2653) -> 4390 | E18: =D18/SUM($D$7:$D$1708) -> 0.0075048251 | F18: =SUM($E$7:E18) -> 0.14374048 | G18: =IF(F18<=70%,"A",IF(F18<=90%,"B","C")) -> A | H18: CILINDRO MESTRE DE FREIO | I18: 5785 (ATE) | 7079433 (OEM) | C2075 (CONTROIL) | RCCD01530 (TRW) | J18: FIAT | K18: =IFERROR(VLOOKUP(A18,'Pedido ESTHER'!$B:$C,2,0),"") | L18: =IF(N(K18)>0,"COMPRA","NÃO COMPRA") -> NÃO COMPRA
A19: SBC1007 | B19: CILINDRO MESTRE DE FREIO GM | C19: =VLOOKUP(A19,[2]Planilha1!$A:$B,2,0) -> #N/A | D19: =SUMIF([1]Relatório!$A$2:$A$2653,A19,[1]Relatório!$AK$2:$AK$2653) -> 4235 | E19: =D19/SUM($D$7:$D$1708) -> 0.0072398484 | F19: =SUM($E$7:E19) -> 0.15098033 | G19: =IF(F19<=70%,"A",IF(F19<=90%,"B","C")) -> A | H19: CILINDRO MESTRE DE FREIO | I19: 0986AB8644 (BOSCH) | 5991 (ATE) | 93289332 (OEM) | C2082 (CONTROIL) | RCCD01620 (TRW) | J19: GM | K19: =IFERROR(VLOOKUP(A19,'Pedido ESTHER'!$B:$C,2,0),"") | L19: =IF(N(K19)>0,"COMPRA","NÃO COMPRA") -> NÃO COMPRA
A20: SBC1011 | B20: CILINDRO MESTRE DE FREIO PEUGEOT | C20: =VLOOKUP(A20,[2]Planilha1!$A:$B,2,0) -> #N/A | D20: =SUMIF([1]Relatório!$A$2:$A$2653,A20,[1]Relatório!$AK$2:$AK$2653) -> 4094 | E20: =D20/SUM($D$7:$D$1708) -> 0.006998805 | F20: =SUM($E$7:E20) -> 0.15797913 | G20: =IF(F20<=70%,"A",IF(F20<=90%,"B","C")) -> A | H20: CILINDRO MESTRE DE FREIO | I20: 0986AB8648 (BOSCH) | 4601F8 (OEM) | 6071 (ATE) | C2130 (CONTROIL) | PMF494 (TRW) | J20: PEUGEOT | K20: =IFERROR(VLOOKUP(A20,'Pedido ESTHER'!$B:$C,2,0),"") -> 4 | L20: =IF(N(K20)>0,"COMPRA","NÃO COMPRA") -> COMPRA
A21: SBC1085 | B21: CILINDRO MESTRE DE FREIO FIAT | C21: =VLOOKUP(A21,[2]Planilha1!$A:$B,2,0) -> #N/A | D21: =SUMIF([1]Relatório!$A$2:$A$2653,A21,[1]Relatório!$AK$2:$AK$2653) -> 4016 | E21: =D21/SUM($D$7:$D$1708) -> 0.0068654619 | F21: =SUM($E$7:E21) -> 0.1648446 | G21: =IF(F21<=70%,"A",IF(F21<=90%,"B","C")) -> A | H21: CILINDRO MESTRE DE FREIO | I21: 7087530 (OEM) | 7402 (ATE) | C2225 (CONTROIL) | J21: FIAT | K21: =IFERROR(VLOOKUP(A21,'Pedido ESTHER'!$B:$C,2,0),"") | L21: =IF(N(K21)>0,"COMPRA","NÃO COMPRA") -> NÃO COMPRA
A22: SBC1135 | B22: CILINDRO MESTRE DE FREIO CITROEN/PEUGEOT | C22: =VLOOKUP(A22,[2]Planilha1!$A:$B,2,0) -> #N/A | D22: =SUMIF([1]Relatório!$A$2:$A$2653,A22,[1]Relatório!$AK$2:$AK$2653) -> 3970 | E22: =D22/SUM($D$7:$D$1708) -> 0.0067868236 | F22: =SUM($E$7:E22) -> 0.17163142 | G22: =IF(F22<=70%,"A",IF(F22<=90%,"B","C")) -> A | H22: CILINDRO MESTRE DE FREIO | I22: 1613317680 (OEM) | C2260 (CONTROIL) | J22: CITROEN / PEUGEOT | K22: =IFERROR(VLOOKUP(A22,'Pedido ESTHER'!$B:$C,2,0),"") | L22: =IF(N(K22)>0,"COMPRA","NÃO COMPRA") -> NÃO COMPRA
A23: SBC1021 | B23: CILINDRO MESTRE DE FREIO FIAT | C23: =VLOOKUP(A23,[2]Planilha1!$A:$B,2,0) -> #N/A | D23: =SUMIF([1]Relatório!$A$2:$A$2653,A23,[1]Relatório!$AK$2:$AK$2653) -> 3303 | E23: =D23/SUM($D$7:$D$1708) -> 0.0056465689 | F23: =SUM($E$7:E23) -> 0.17727799 | G23: =IF(F23<=70%,"A",IF(F23<=90%,"B","C")) -> A | H23: CILINDRO MESTRE DE FREIO | I23: 5766 (ATE) | 7074619 (OEM) | C2033 (CONTROIL) | RCCD00890 (TRW) | J23: FIAT | K23: =IFERROR(VLOOKUP(A23,'Pedido ESTHER'!$B:$C,2,0),"") | L23: =IF(N(K23)>0,"COMPRA","NÃO COMPRA") -> NÃO COMPRA
A24: SBC1134 | B24: CILINDRO MESTRE DE FREIO RENAULT | C24: =VLOOKUP(A24,[2]Planilha1!$A:$B,2,0) -> #N/A | D24: =SUMIF([1]Relatório!$A$2:$A$2653,A24,[1]Relatório!$AK$2:$AK$2653) -> 3257 | E24: =D24/SUM($D$7:$D$1708) -> 0.0055679306 | F24: =SUM($E$7:E24) -> 0.18284592 | G24: =IF(F24<=70%,"A",IF(F24<=90%,"B","C")) -> A | H24: CILINDRO MESTRE DE FREIO | I24: 0204798374 (BOSCH) | 460119216R (OEM) | C2263 (CONTROIL) | J24: RENAULT | K24: =IFERROR(VLOOKUP(A24,'Pedido ESTHER'!$B:$C,2,0),"") | L24: =IF(N(K24)>0,"COMPRA","NÃO COMPRA") -> NÃO COMPRA
A25: SBC1090 | B25: CILINDRO MESTRE DE FREIO VW | C25: =VLOOKUP(A25,[2]Planilha1!$A:$B,2,0) -> #N/A | D25: =SUMIF([1]Relatório!$A$2:$A$2653,A25,[1]Relatório!$AK$2:$AK$2653) -> 3160 | E25: =D25/SUM($D$7:$D$1708) -> 0.0054021065 | F25: =SUM($E$7:E25) -> 0.18824803 | G25: =IF(F25<=70%,"A",IF(F25<=90%,"B","C")) -> A | H25: CILINDRO MESTRE DE FREIO | J25: VOLKSWAGEN | K25: =IFERROR(VLOOKUP(A25,'Pedido ESTHER'!$B:$C,2,0),"") | L25: =IF(N(K25)>0,"COMPRA","NÃO COMPRA") -> NÃO COMPRA
A26: SBC1081 | B26: CILINDRO MESTRE DE FREIO VW | C26: =VLOOKUP(A26,[2]Planilha1!$A:$B,2,0) -> #N/A | D26: =SUMIF([1]Relatório!$A$2:$A$2653,A26,[1]Relatório!$AK$2:$AK$2653) -> 3118 | E26: =D26/SUM($D$7:$D$1708) -> 0.0053303063 | F26: =SUM($E$7:E26) -> 0.19357833 | G26: =IF(F26<=70%,"A",IF(F26<=90%,"B","C")) -> A | H26: CILINDRO MESTRE DE FREIO | I26: 0986AB8572 (BOSCH) | 5Z0611019N (OEM) | C2160 (CONTROIL) | J26: VOLKSWAGEN | K26: =IFERROR(VLOOKUP(A26,'Pedido ESTHER'!$B:$C,2,0),"") | L26: =IF(N(K26)>0,"COMPRA","NÃO COMPRA") -> NÃO COMPRA
A27: SWC5006 | B27: CILINDRO DE RODA LE/LD RENAULT/VW | C27: =VLOOKUP(A27,[2]Planilha1!$A:$B,2,0) -> #N/A | D27: =SUMIF([1]Relatório!$A$2:$A$2653,A27,[1]Relatório!$AK$2:$AK$2653) -> 3108 | E27: =D27/SUM($D$7:$D$1708) -> 0.0053132111 | F27: =SUM($E$7:E27) -> 0.19889154 | G27: =IF(F27<=70%,"A",IF(F27<=90%,"B","C")) -> A | H27: CILINDRO DE RODA | I27: 0986AB8653 (BOSCH) | 6001551410 (OEM) | C3537 (CONTROIL) | CCR92250 (FORTEC) | RCCR03580 (TRW) | J27: RENAULT / VOLKSWAGEN | K27: =IFERROR(VLOOKUP(A27,'Pedido ESTHER'!$B:$C,2,0),"") | L27: =IF(N(K27)>0,"COMPRA","NÃO COMPRA") -> NÃO COMPRA
A28: SWC5015 | B28: CILINDRO DE RODA LE/LD GM | C28: =VLOOKUP(A28,[2]Planilha1!$A:$B,2,0) -> #N/A | D28: =SUMIF([1]Relatório!$A$2:$A$2653,A28,[1]Relatório!$AK$2:$AK$2653) -> 3004 | E28: =D28/SUM($D$7:$D$1708) -> 0.0051354202 | F28: =SUM($E$7:E28) -> 0.20402696 | G28: =IF(F28<=70%,"A",IF(F28<=90%,"B","C")) -> A | H28: CILINDRO DE RODA | I28: 0986AB8667 (BOSCH) | 7630 (ATE) | 93313891 (OEM) | C3521 (CONTROIL) | CCR92241 (FORTEC) | CR2202 (BOSCH) | J28: GM | K28: =IFERROR(VLOOKUP(A28,'Pedido ESTHER'!$B:$C,2,0),"") | L28: =IF(N(K28)>0,"COMPRA","NÃO COMPRA") -> NÃO COMPRA
A29: SVP6031 | B29: BOMBA DE VÁCUO FIAT/JEEP | C29: =VLOOKUP(A29,[2]Planilha1!$A:$B,2,0) -> #N/A | D29: =SUMIF([1]Relatório!$A$2:$A$2653,A29,[1]Relatório!$AK$2:$AK$2653) -> 2917 | E29: =D29/SUM($D$7:$D$1708) -> 0.0049866913 | F29: =SUM($E$7:E29) -> 0.20901365 | G29: =IF(F29<=70%,"A",IF(F29<=90%,"B","C")) -> A | H29: BOMBA DE VÁCUO | J29: FIAT / JEEP | K29: =IFERROR(VLOOKUP(A29,'Pedido ESTHER'!$B:$C,2,0),"") | L29: =IF(N(K29)>0,"COMPRA","NÃO COMPRA") -> NÃO COMPRA
A30: SCC2029 | B30: CILINDRO MESTRE DE EMBREAGEM RENAULT | C30: =VLOOKUP(A30,[2]Planilha1!$A:$B,2,0) -> #N/A | D30: =SUMIF([1]Relatório!$A$2:$A$2653,A30,[1]Relatório!$AK$2:$AK$2653) -> 2843 | E30: =D30/SUM($D$7:$D$1708) -> 0.0048601863 | F30: =SUM($E$7:E30) -> 0.21387384 | G30: =IF(F30<=70%,"A",IF(F30<=90%,"B","C")) -> A | H30: CILINDRO MESTRE DE EMBREAGEM | I30: 306107623R (RENAULT) | J30: RENAULT | K30: =IFERROR(VLOOKUP(A30,'Pedido ESTHER'!$B:$C,2,0),"") -> 4 | L30: =IF(N(K30)>0,"COMPRA","NÃO COMPRA") -> COMPRA
A31: SBC1097 | B31: CILINDRO MESTRE DE FREIO RENAULT | C31: =VLOOKUP(A31,[2]Planilha1!$A:$B,2,0) -> #N/A | D31: =SUMIF([1]Relatório!$A$2:$A$2653,A31,[1]Relatório!$AK$2:$AK$2653) -> 2757 | E31: =D31/SUM($D$7:$D$1708) -> 0.004713167 | F31: =SUM($E$7:E31) -> 0.21858701 | G31: =IF(F31<=70%,"A",IF(F31<=90%,"B","C")) -> A | H31: CILINDRO MESTRE DE FREIO | I31: 460114036R (OEM) | 6371 (ATE) | 6966 (ATE) | C2204 (CONTROIL) | J31: RENAULT | K31: =IFERROR(VLOOKUP(A31,'Pedido ESTHER'!$B:$C,2,0),"") | L31: =IF(N(K31)>0,"COMPRA","NÃO COMPRA") -> NÃO COMPRA
A32: SBC1027 | B32: CILINDRO MESTRE DE FREIO FORD | C32: =VLOOKUP(A32,[2]Planilha1!$A:$B,2,0) -> #N/A | D32: =SUMIF([1]Relatório!$A$2:$A$2653,A32,[1]Relatório!$AK$2:$AK$2653) -> 2683 | E32: =D32/SUM($D$7:$D$1708) -> 0.0045866619 | F32: =SUM($E$7:E32) -> 0.22317367 | G32: =IF(F32<=70%,"A",IF(F32<=90%,"B","C")) -> A | H32: CILINDRO MESTRE DE FREIO | I32: C2061 (CONTROIL) | RCCD00910 (TRW) | J32: FORD | K32: =IFERROR(VLOOKUP(A32,'Pedido ESTHER'!$B:$C,2,0),"") | L32: =IF(N(K32)>0,"COMPRA","NÃO COMPRA") -> NÃO COMPRA
A33: SWC5032 | B33: CILINDRO DE RODA LE/LD FIAT | C33: =VLOOKUP(A33,[2]Planilha1!$A:$B,2,0) -> #N/A | D33: =SUMIF([1]Relatório!$A$2:$A$2653,A33,[1]Relatório!$AK$2:$AK$2653) -> 2549 | E33: =D33/SUM($D$7:$D$1708) -> 0.0043575853 | F33: =SUM($E$7:E33) -> 0.22753125 | G33: =IF(F33<=70%,"A",IF(F33<=90%,"B","C")) -> A | H33: CILINDRO DE RODA | I33: 0986AB8658 (BOSCH) | 5684 (ATE) | 71737949 (OEM) | 71737950 (OEM) | 7729634 (OEM) | 7757604 (OEM) | C3411 (CONTROIL) | CCR9230 (FORTEC) | CR1687 (BOSCH) | RCCR02120 (TRW) | J33: FIAT | K33: =IFERROR(VLOOKUP(A33,'Pedido ESTHER'!$B:$C,2,0),"") | L33: =IF(N(K33)>0,"COMPRA","NÃO COMPRA") -> NÃO COMPRA
A34: SCC2073 | B34: CILINDRO MESTRE DE EMBREAGEM RENAULT | C34: =VLOOKUP(A34,[2]Planilha1!$A:$B,2,0) -> #N/A | D34: =SUMIF([1]Relatório!$A$2:$A$2653,A34,[1]Relatório!$AK$2:$AK$2653) -> 2503 | E34: =D34/SUM($D$7:$D$1708) -> 0.004278947 | F34: =SUM($E$7:E34) -> 0.2318102 | G34: =IF(F34<=70%,"A",IF(F34<=90%,"B","C")) -> A | H34: CILINDRO MESTRE DE EMBREAGEM | J34: RENAULT | K34: =IFERROR(VLOOKUP(A34,'Pedido ESTHER'!$B:$C,2,0),"") | L34: =IF(N(K34)>0,"COMPRA","NÃO COMPRA") -> NÃO COMPRA
A35: SBC1005 | B35: CILINDRO MESTRE DE FREIO VW | C35: =VLOOKUP(A35,[2]Planilha1!$A:$B,2,0) -> #N/A | D35: =SUMIF([1]Relatório!$A$2:$A$2653,A35,[1]Relatório!$AK$2:$AK$2653) -> 2390 | E35: =D35/SUM($D$7:$D$1708) -> 0.0040857704 | F35: =SUM($E$7:E35) -> 0.23589597 | G35: =IF(F35<=70%,"A",IF(F35<=90%,"B","C")) -> A | H35: CILINDRO MESTRE DE FREIO | I35: 0986AB8602 (BOSCH) | 30561101513 (OEM) | 5849 (ATE) | C2000 (CONTROIL) | RCCD00680 (TRW) | J35: VOLKSWAGEN | K35: =IFERROR(VLOOKUP(A35,'Pedido ESTHER'!$B:$C,2,0),"") | L35: =IF(N(K35)>0,"COMPRA","NÃO COMPRA") -> NÃO COMPRA
A36: SBC1042 | B36: CILINDRO MESTRE DE FREIO GM | C36: =VLOOKUP(A36,[2]Planilha1!$A:$B,2,0) -> #N/A | D36: =SUMIF([1]Relatório!$A$2:$A$2653,A36,[1]Relatório!$AK$2:$AK$2653) -> 2389 | E36: =D36/SUM($D$7:$D$1708) -> 0.0040840609 | F36: =SUM($E$7:E36) -> 0.23998003 | G36: =IF(F36<=70%,"A",IF(F36<=90%,"B","C")) -> A | H36: CILINDRO MESTRE DE FREIO | J36: GM | K36: =IFERROR(VLOOKUP(A36,'Pedido ESTHER'!$B:$C,2,0),"") | L36: =IF(N(K36)>0,"COMPRA","NÃO COMPRA") -> NÃO COMPRA
A37: SWC5011 | B37: CILINDRO DE RODA LE/LD GM | C37: =VLOOKUP(A37,[2]Planilha1!$A:$B,2,0) -> #N/A | D37: =SUMIF([1]Relatório!$A$2:$A$2653,A37,[1]Relatório!$AK$2:$AK$2653) -> 2282 | E37: =D37/SUM($D$7:$D$1708) -> 0.0039011415 | F37: =SUM($E$7:E37) -> 0.24388117 | G37: =IF(F37<=70%,"A",IF(F37<=90%,"B","C")) -> A | H37: CILINDRO DE RODA | I37: 0986AB8656 (BOSCH) | 95018639 (OEM) | 95231320 (OEM) | BWD6000 (TRW) | C3426 (CONTROIL) | CCR92267 (FORTEC) | J37: GM | K37: =IFERROR(VLOOKUP(A37,'Pedido ESTHER'!$B:$C,2,0),"") | L37: =IF(N(K37)>0,"COMPRA","NÃO COMPRA") -> NÃO COMPRA
A38: SSC3024 | B38: CILINDRO AUXILIAR DE EMBREAGEM JAC | C38: =VLOOKUP(A38,[2]Planilha1!$A:$B,2,0) -> #N/A | D38: =SUMIF([1]Relatório!$A$2:$A$2653,A38,[1]Relatório!$AK$2:$AK$2653) -> 2255 | E38: =D38/SUM($D$7:$D$1708) -> 0.0038549842 | F38: =SUM($E$7:E38) -> 0.24773616 | G38: =IF(F38<=70%,"A",IF(F38<=90%,"B","C")) -> A | H38: CILINDRO AUXILIAR DE EMBREAGEM | J38: JAC MOTORS | K38: =IFERROR(VLOOKUP(A38,'Pedido ESTHER'!$B:$C,2,0),"") | L38: =IF(N(K38)>0,"COMPRA","NÃO COMPRA") -> NÃO COMPRA
A39: SCC2083 | B39: CILINDRO MESTRE DE EMBREAGEM GM | C39: =VLOOKUP(A39,[2]Planilha1!$A:$B,2,0) -> #N/A | D39: =SUMIF([1]Relatório!$A$2:$A$2653,A39,[1]Relatório!$AK$2:$AK$2653) -> 2204 | E39: =D39/SUM($D$7:$D$1708) -> 0.0037677983 | F39: =SUM($E$7:E39) -> 0.25150396 | G39: =IF(F39<=70%,"A",IF(F39<=90%,"B","C")) -> A | H39: CILINDRO MESTRE DE EMBREAGEM | J39: GM | K39: =IFERROR(VLOOKUP(A39,'Pedido ESTHER'!$B:$C,2,0),"") | L39: =IF(N(K39)>0,"COMPRA","NÃO COMPRA") -> NÃO COMPRA
A40: SWC5013 | B40: CILINDRO DE RODA LE/LD FIAT | C40: =VLOOKUP(A40,[2]Planilha1!$A:$B,2,0) -> #N/A | D40: =SUMIF([1]Relatório!$A$2:$A$2653,A40,[1]Relatório!$AK$2:$AK$2653) -> 2162 | E40: =D40/SUM($D$7:$D$1708) -> 0.0036959982 | F40: =SUM($E$7:E40) -> 0.25519995 | G40: =IF(F40<=70%,"A",IF(F40<=90%,"B","C")) -> A | H40: CILINDRO DE RODA | I40: 6987 (ATE) | 7088827 (OEM) | C3429 (CONTROIL) | CCR92283 (FORTEC) | J40: FIAT | K40: =IFERROR(VLOOKUP(A40,'Pedido ESTHER'!$B:$C,2,0),"") -> 20 | L40: =IF(N(K40)>0,"COMPRA","NÃO COMPRA") -> COMPRA
A41: SBC1099 | B41: CILINDRO MESTRE DE FREIO GM | C41: =VLOOKUP(A41,[2]Planilha1!$A:$B,2,0) -> #N/A | D41: =SUMIF([1]Relatório!$A$2:$A$2653,A41,[1]Relatório!$AK$2:$AK$2653) -> 2119 | E41: =D41/SUM($D$7:$D$1708) -> 0.0036224885 | F41: =SUM($E$7:E41) -> 0.25882244 | G41: =IF(F41<=70%,"A",IF(F41<=90%,"B","C")) -> A | H41: CILINDRO MESTRE DE FREIO | I41: 0986AB8570 (BOSCH) | 6476 (ATE) | 94735981 (OEM) | C-2174 (CONTROIL) | PMF6000 (TRW) | J41: GM | K41: =IFERROR(VLOOKUP(A41,'Pedido ESTHER'!$B:$C,2,0),"") | L41: =IF(N(K41)>0,"COMPRA","NÃO COMPRA") -> NÃO COMPRA
A42: SCC2058 | B42: CILINDRO MESTRE DE EMBREAGEM RENAULT | C42: =VLOOKUP(A42,[2]Planilha1!$A:$B,2,0) -> #N/A | D42: =SUMIF([1]Relatório!$A$2:$A$2653,A42,[1]Relatório!$AK$2:$AK$2653) -> 2113 | E42: =D42/SUM($D$7:$D$1708) -> 0.0036122313 | F42: =SUM($E$7:E42) -> 0.26243467 | G42: =IF(F42<=70%,"A",IF(F42<=90%,"B","C")) -> A | H42: CILINDRO MESTRE DE EMBREAGEM | I42: 6001548446 (RENAULT) | 8200424004 (RENAULT) | 8200424007 (RENAULT) | J42: RENAULT | K42: =IFERROR(VLOOKUP(A42,'Pedido ESTHER'!$B:$C,2,0),"") | L42: =IF(N(K42)>0,"COMPRA","NÃO COMPRA") -> NÃO COMPRA
A43: SOC9000 | B43: RESFRIADOR OLEO FIAT | C43: =VLOOKUP(A43,[2]Planilha1!$A:$B,2,0) -> #N/A | D43: =SUMIF([1]Relatório!$A$2:$A$2653,A43,[1]Relatório!$AK$2:$AK$2653) -> 2094 | E43: =D43/SUM($D$7:$D$1708) -> 0.0035797503 | F43: =SUM($E$7:E43) -> 0.26601442 | G43: =IF(F43<=70%,"A",IF(F43<=90%,"B","C")) -> A | H43: RESFRIADOR DE ÓLEO CÂMBIO | I43: 7089720 (OEM) | J43: BMW / FIAT / JEEP / MINI | K43: =IFERROR(VLOOKUP(A43,'Pedido ESTHER'!$B:$C,2,0),"") | L43: =IF(N(K43)>0,"COMPRA","NÃO COMPRA") -> NÃO COMPRA
...

Sheet Pedido ESTHER
A1: CÓDIGO (como veio no pedido) | B1: CÓDIGO (sem espaço) | C1: QUANTIDADE
A2: SBC 1011 | B2: =UPPER(SUBSTITUTE(TRIM(A2)," ","")) -> SBC1011 | C2: 4
A3: SBC 1117 | B3: =UPPER(SUBSTITUTE(TRIM(A3)," ","")) -> SBC1117 | C3: 6
A4: SBC 1124 | B4: =UPPER(SUBSTITUTE(TRIM(A4)," ","")) -> SBC1124 | C4: 6
A5: SBC 1147 | B5: =UPPER(SUBSTITUTE(TRIM(A5)," ","")) -> SBC1147 | C5: 4
A6: SBC 1148 | B6: =UPPER(SUBSTITUTE(TRIM(A6)," ","")) -> SBC1148 | C6: 6
A7: SBC 1149 | B7: =UPPER(SUBSTITUTE(TRIM(A7)," ","")) -> SBC1149 | C7: 6
A8: SBC 1188 | B8: =UPPER(SUBSTITUTE(TRIM(A8)," ","")) -> SBC1188 | C8: 8
A9: SCA 8053 FL | B9: =UPPER(SUBSTITUTE(TRIM(A9)," ","")) -> SCA8053FL | C9: 3
A10: SCA 8053 FR | B10: =UPPER(SUBSTITUTE(TRIM(A10)," ","")) -> SCA8053FR | C10: 3
A11: SCA 8060 FL | B11: =UPPER(SUBSTITUTE(TRIM(A11)," ","")) -> SCA8060FL | C11: 3
A12: SCA 8060 FR | B12: =UPPER(SUBSTITUTE(TRIM(A12)," ","")) -> SCA8060FR | C12: 3
A13: SCC 2010 | B13: =UPPER(SUBSTITUTE(TRIM(A13)," ","")) -> SCC2010 | C13: 8
... A26: SCC 2003 | B26: =UPPER(SUBSTITUTE(TRIM(A26)," ","")) -> SCC2003 | C26: 10
B27: =UPPER(SUBSTITUTE(TRIM(A27)," ",""))
B28: =UPPER(SUBSTITUTE(TRIM(A28)," ",""))
B29: =UPPER(SUBSTITUTE(TRIM(A29)," ",""))
B30: =UPPER(SUBSTITUTE(TRIM(A30)," ",""))
B31: =UPPER(SUBSTITUTE(TRIM(A31)," ",""))
B32: =UPPER(SUBSTITUTE(TRIM(A32)," ",""))
B33: =UPPER(SUBSTITUTE(TRIM(A33)," ",""))
B34: =UPPER(SUBSTITUTE(TRIM(A34)," ",""))
B35: =UPPER(SUBSTITUTE(TRIM(A35)," ",""))
B36: =UPPER(SUBSTITUTE(TRIM(A36)," ",""))
B37: =UPPER(SUBSTITUTE(TRIM(A37)," ",""))
B38: =UPPER(SUBSTITUTE(TRIM(A38)," ",""))
... B151: =UPPER(SUBSTITUTE(TRIM(A151)," ",""))
