Workbook
Name Slicer_moto: #N/A
Name Slicer_Curva: #N/A
Name Slicer_Família: #N/A
Name Slicer_Aplic: #N/A
Name Slicer_Montadora: #N/A

Sheet MATRIZ
A2: codigoProduto | C2: Produto | D2: APLICAÇÃO | E2: FAMÍLIA | F2: MONTADORA | G2: CURVA EMPROL PA | H2: CROSS | J2: MOTOR | K2: VALOR LIQ. | L2: QTD PEDIDO | M2: COMPRA / NÃO COMPRA
A3: codigoProduto | B3: Coluna1 | C3: Produto | D3: APLICAÇÃO | E3: FAMÍLIA | F3: MONTADORA | G3: CURVA | H3: CROSS | I3: Coluna3 | J3: MOTOR | K3: Coluna2 | L3: QTD PEDIDO | M3: COMPRA / NÃO COMPRA
A4: 581450101 | C4: ANEL PISTÃO VW GOL/FOX 1.6 8V EA111 STD (LL) | D4: LEVE | E4: ANEL DE PISTAO | F4: VOLKSWAGEN | G4: A | H4: 2C5294 (HASTINGS) A0700589 (MAHLE) A530 (SINTECH) TA8126 (METAL LEVE) | J4: 4 CILINDROS | L4: =IFERROR(VLOOKUP(A4,PEDIDO!$B:$C,2,0),"") | M4: =IF(N(L4)>0,"COMPRA","NÃO COMPRA") -> NÃO COMPRA
A5: 580050701 | C5: ANEL PISTÃO FIAT UNO 1.0 8V/16V FIRE STD (LL) | D5: LEVE | E5: ANEL DE PISTAO | F5: FIAT | G5: A | H5: 2C5051 (HASTINGS) 800051340 (KS) A240 (SINTECH) A25910 (MAHLE) A25919 (SPA MAHLE) ASFI10A-STD (TAKAO) EMA7611 (CENTRINEL) STA7508 (MAHLE) STD7508 (SPA METAL LEVE) TD7508 (METAL LEVE) | J5: 4 CILINDROS | L5: =IFERROR(VLOOKUP(A5,PEDIDO!$B:$C,2,0),"") | M5: =IF(N(L5)>0,"COMPRA","NÃO COMPRA") -> NÃO COMPRA
A6: 581430101 | C6: ANEL PISTÃO VW GOL/FOX 1.0 8V EA111 STD (LL) | D6: LEVE | E6: ANEL DE PISTAO | F6: VOLKSWAGEN | G6: A | H6: 2C5207 (REF.) A540 (REF.) A70650 (REF.) TA8566 (REF.) | J6: 4 CILINDROS | L6: =IFERROR(VLOOKUP(A6,PEDIDO!$B:$C,2,0),"") | M6: =IF(N(L6)>0,"COMPRA","NÃO COMPRA") -> NÃO COMPRA
A7: 581110701 | C7: ANEL PISTÃO FIAT PALIO 1.4 FIRE FLEX STD (LL) | D7: LEVE | E7: ANEL DE PISTAO | F7: FIAT | G7: A | H7: 2C5266 (HASTINGS) 800065040 (KS) A25140 (MAHLE) A260 (SINTECH) ASFI14-STD (TAKAO) EMA7615 (CENTRINEL) TT8330 (METAL LEVE) | J7: 4 CILINDROS | L7: =IFERROR(VLOOKUP(A7,PEDIDO!$B:$C,2,0),"") | M7: =IF(N(L7)>0,"COMPRA","NÃO COMPRA") -> NÃO COMPRA
A8: 580310101 | C8: ANEL PISTÃO VW GOL 1.0 8/16V AT/EA111 STD (LL) | D8: LEVE | E8: ANEL DE PISTAO | F8: VOLKSWAGEN | G8: A | H8: 2C4808 (HASTINGS) 70500 (MAHLE) 800053741000 (KS) A500 (SINTECH) A70560 (MAHLE) ASVW10A-STD (TAKAO) EMA7813 (CENTRINEL) TA7251/7224 (METAL LEVE) | J8: 4 CILINDROS | L8: =IFERROR(VLOOKUP(A8,PEDIDO!$B:$C,2,0),"") | M8: =IF(N(L8)>0,"COMPRA","NÃO COMPRA") -> NÃO COMPRA
A9: 581070301 | C9: ANEL PISTÃO FORD FIESTA 1.0 8V ZETECFLEX STD (LL) | D9: LEVE | E9: ANEL DE PISTAO | F9: FORD | G9: A | H9: 2C5205 (HASTINGS) 800064440 (KS) A450 (SINTECH) A59870 (MAHLE) ASFO10A-STD (TAKAO) EMA7717 (CENTRINEL) TA7453 (METAL LEVE) | J9: 4 CILINDROS | L9: =IFERROR(VLOOKUP(A9,PEDIDO!$B:$C,2,0),"") | M9: =IF(N(L9)>0,"COMPRA","NÃO COMPRA") -> NÃO COMPRA
A10: 580570401 | C10: ANEL PISTÃO GM CORSA 1.0 8V EFI STD (LL) | D10: LEVE | E10: ANEL DE PISTAO | F10: CHEVROLET | G10: A | H10: 2C4517 (HASTINGS) 93221881 (KS) A14140 (MAHLE) A14149 (SPA MAHLE) A145 (SINTECH) ASGM10-STD (TAKAO) DA7092 (METAL LEVE) PNA7518 (CENTRINEL) SDA7092 (SPA METAL LEVE) | J10: 4 CILINDROS | L10: =IFERROR(VLOOKUP(A10,PEDIDO!$B:$C,2,0),"") | M10: =IF(N(L10)>0,"COMPRA","NÃO COMPRA") -> NÃO COMPRA
A11: 580315101 | C11: ANEL PISTÃO VW GOL 1.0 8/16V AT/EA111 +050 (LL) | D11: LEVE | E11: ANEL DE PISTAO | F11: VOLKSWAGEN | G11: A | H11: 2C4808020 (HASTINGS) 70500 (MAHLE) 800053741050 (KS) A500 (SINTECH) A70560 (MAHLE) ASVW10A-050 (TAKAO) EMA7813 (CENTRINEL) TA7251/7224 (METAL LEVE) | J11: 4 CILINDROS | L11: =IFERROR(VLOOKUP(A11,PEDIDO!$B:$C,2,0),"") | M11: =IF(N(L11)>0,"COMPRA","NÃO COMPRA") -> NÃO COMPRA
A12: 580054701 | C12: ANEL PISTÃO FIAT UNO 1.0 8V/16V FIRE +040 (LL) | D12: LEVE | E12: ANEL DE PISTAO | F12: FIAT | G12: A | H12: 2C5051016 (HASTINGS) 800051340 (KS) A240 (SINTECH) A25910 (MAHLE) A25919 (SPA MAHLE) ASFI10A-040 (TAKAO) EMA7611 (CENTRINEL) STA7508 (MAHLE) STD7508 (SPA METAL LEVE) TD7508 (METAL LEVE) | J12: 4 CILINDROS | L12: =IFERROR(VLOOKUP(A12,PEDIDO!$B:$C,2,0),"") | M12: =IF(N(L12)>0,"COMPRA","NÃO COMPRA") -> NÃO COMPRA
A13: 580380101 | C13: ANEL PISTÃO VW SANTANA/APOLO 16/18 AP STD (LL) | D13: LEVE | E13: ANEL DE PISTAO | F13: VOLKSWAGEN | G13: A | H13: 2C4341 (HASTINGS) 800001043 (KS) A580 (SINTECH) A70680 (MAHLE) A70689 (SPA MAHLE) ASVW18A-STD (TAKAO) DA6563 (METAL LEVE) PNA7710 (CENTRINEL) SNA6563 (SPA METAL LEVE) | J13: 4 CILINDROS | L13: =IFERROR(VLOOKUP(A13,PEDIDO!$B:$C,2,0),"") | M13: =IF(N(L13)>0,"COMPRA","NÃO COMPRA") -> NÃO COMPRA
A14: 580610401 | C14: ANEL PISTÃO FIAT PALIO/MERIVA 18 8/16V STD (LL) | D14: LEVE | E14: ANEL DE PISTAO | F14: CHEVROLET | G14: A | H14: 2C5185 (HASTINGS) 800038940 (KS) 93294731 (ORIG.) A14195 (MAHLE) A175 (SINTECH) EMA7613 (CENTRINEL) TA7268 (METAL LEVE) | J14: 4 CILINDROS | L14: =IFERROR(VLOOKUP(A14,PEDIDO!$B:$C,2,0),"") | M14: =IF(N(L14)>0,"COMPRA","NÃO COMPRA") -> NÃO COMPRA
A15: 580030701 | C15: ANEL PISTÃO FIAT PALIO 1.0/1.5 FIASA STD (LL) | D15: LEVE | E15: ANEL DE PISTAO | F15: FIAT | G15: A | H15: 2C4932 (HASTINGS) 800061741 (KS) A250 (SINTECH) A25010 (MAHLE) A25019 (SPA MAHLE) ASFI10-STD (TAKAO) DD6983 (METAL LEVE) DD7390 (METAL LEVE) DD7391 (METAL LEVE) PNA7603 (CENTRINEL) SDD6983 (SPA METAL LEVE) SNA7390 (SPA METAL LEVE) | J15: 4 CILINDROS | L15: =IFERROR(VLOOKUP(A15,PEDIDO!$B:$C,2,0),"") | M15: =IF(N(L15)>0,"COMPRA","NÃO COMPRA") -> NÃO COMPRA
... A129: 583070101 | C129: ANEL PISTÃO EA211 MSI 1.6 16V DOHC L4 FLEX STD | D129: LEVE | E129: ANEL DE PISTAO | F129: VOLKSWAGEN | G129: C | H129: 2C5438 (HASTINGS) A0701030 (MAHLE) A535 (SINTECH) TS.9037 (METAL LEVE) | J129: 4 CILINDROS | L129: =IFERROR(VLOOKUP(A129,PEDIDO!$B:$C,2,0),"") | M129: =IF(N(L129)>0,"COMPRA","NÃO COMPRA") -> NÃO COMPRA
A130: 583674701 | C130: ANEL PISTÃO FIREFLY 1.3 8V L4 FLEX - +0,4 | D130: LEVE | E130: ANEL DE PISTAO | F130: FIAT | G130: C | H130: #N/A | J130: 4 CILINDROS | L130: =IFERROR(VLOOKUP(A130,PEDIDO!$B:$C,2,0),"") | M130: =IF(N(L130)>0,"COMPRA","NÃO COMPRA") -> NÃO COMPRA
A131: 580409101 | C131: ANEL PISTÃO VW GOL/PARATI 16/18 AP MI +100 (LL) | D131: LEVE | E131: ANEL DE PISTAO | F131: VOLKSWAGEN | G131: C | H131: 2C5095040 (HASTINGS) A510 (SINTECH) A70810 (MAHLE) A70819 (SPA MAHLE) ASVW18B-100 (TAKAO) EMA7814 (CENTRINEL) STA7215 (SPA METAL LEVE) TA7215 (METAL LEVE) | J131: 4 CILINDROS | L131: =IFERROR(VLOOKUP(A131,PEDIDO!$B:$C,2,0),"") | M131: =IF(N(L131)>0,"COMPRA","NÃO COMPRA") -> NÃO COMPRA
A132: 582375101 | C132: ANEL PISTÃO EA211 MPI 1.0 L 12V L3 (13-) +0,5 | D132: LEVE | E132: ANEL DE PISTAO | F132: VOLKSWAGEN | G132: C | H132: 2N5672 (HASTINGS) A0701020 (MAHLE) A515 (SINTECH) TS.9032 (METAL LEVE) | J132: 3 CILINDROS | L132: =IFERROR(VLOOKUP(A132,PEDIDO!$B:$C,2,0),"") | M132: =IF(N(L132)>0,"COMPRA","NÃO COMPRA") -> NÃO COMPRA
A133: 582870401 | C133: ANEL DE PISTAO SPE/4 1.0 L 8V SOHC L4 FLEX STD | D133: LEVE | E133: ANEL DE PISTAO | F133: CHEVROLET | G133: C | H133: 98500210 (CHEVROLET) | J133: 4 CILINDROS | L133: =IFERROR(VLOOKUP(A133,PEDIDO!$B:$C,2,0),"") | M133: =IF(N(L133)>0,"COMPRA","NÃO COMPRA") -> NÃO COMPRA
A134: 583085101 | C134: ANEL PISTÃO VW 1.6 8V - EA111 VW 1.4 050 | D134: LEVE | E134: ANEL DE PISTAO | F134: VOLKSWAGEN | G134: C | H134: 2C5177020 (HASTINGS) 800026140 (KS) A0700589 (MAHLE) A530 (SINTECH) A70580 (MAHLE) STA8126 (METAL LEVE) TA.8126 (METAL LEVE) | J134: 4 CILINDROS | L134: =IFERROR(VLOOKUP(A134,PEDIDO!$B:$C,2,0),"") | M134: =IF(N(L134)>0,"COMPRA","NÃO COMPRA") -> NÃO COMPRA
A135: 581089401 | C135: ANEL PISTÃO GM CELTA/CORSA 1.4 8V +100 (LL) | D135: LEVE | E135: ANEL DE PISTAO | F135: CHEVROLET | G135: C | H135: 2C4812040 (HASTINGS) 800020541 (KS) 93227616 (ORIG.) A14530 (MAHLE) A14539 (SPA MAHLE) A14840 (MAHLE) A170 0,50 (SINTECH) ASGM14-100 (TAKAO) DA7093 (METAL LEVE) DA8405 (METAL LEVE) PNA7519 (CENTRINEL) SNA7093 (SPA METAL LEVE) | J135: 4 CILINDROS | L135: =IFERROR(VLOOKUP(A135,PEDIDO!$B:$C,2,0),"") | M135: =IF(N(L135)>0,"COMPRA","NÃO COMPRA") -> NÃO COMPRA
A136: 582935641 | C136: ANEL PISTÃO KAPPA 1.0 12V L3 DOHC FLEX 050 | D136: LEVE | E136: ANEL DE PISTAO | F136: HYUNDAI | G136: C | H136: 2C408650 (HASTINGS) 800141330 (KS) A2080610 (MAHLE) A310 (SINTECH) AR.9072 (METAL LEVE) | J136: 3 CILINDROS | L136: =IFERROR(VLOOKUP(A136,PEDIDO!$B:$C,2,0),"") | M136: =IF(N(L136)>0,"COMPRA","NÃO COMPRA") -> NÃO COMPRA
A137: 582920451 | C137: ANEL PISTÃO D17Z 1.7 L 16V SOHC L4 GASOLINA STD | D137: LEVE | E137: ANEL DE PISTAO | F137: HONDA | G137: C | H137: 2C5111 (HASTINGS) A51280 (MAHLE) A770 (SINTECH) AA.8451 (METAL LEVE) | J137: 4 CILINDROS | L137: =IFERROR(VLOOKUP(A137,PEDIDO!$B:$C,2,0),"") | M137: =IF(N(L137)>0,"COMPRA","NÃO COMPRA") -> NÃO COMPRA
A138: 582455071 | C138: ANEL PISTÃO NISSAN MARCH, VERSA 1.6 16V 050 | D138: LEVE | E138: ANEL DE PISTAO | F138: NISSAN | G138: C | H138: 2C4439020 (HASTINGS) A0030620 (MAHLE) PR.9052 (METAL LEVE) | J138: 4 CILINDROS | L138: =IFERROR(VLOOKUP(A138,PEDIDO!$B:$C,2,0),"") | M138: =IF(N(L138)>0,"COMPRA","NÃO COMPRA") -> NÃO COMPRA
A139: 583670701 | C139: ANEL PISTÃO FIREFLY 1.3 8V L4 FLEX - STD | D139: LEVE | E139: ANEL DE PISTAO | F139: FIAT | G139: C | H139: #N/A | J139: 4 CILINDROS | L139: =IFERROR(VLOOKUP(A139,PEDIDO!$B:$C,2,0),"") | M139: =IF(N(L139)>0,"COMPRA","NÃO COMPRA") -> NÃO COMPRA
A140: 581485101 | C140: ANEL PISTÃO VW AMAROK 2.0 16V TURBO 0,50 ³ | D140: UTILITÁRIO | E140: ANEL DE PISTAO | F140: VOLKSWAGEN | G140: C | H140: 2D7255 (HASTINGS) A0701010 (MAHLE) DC9006 (METAL LEVE) | J140: 4 CILINDROS | L140: =IFERROR(VLOOKUP(A140,PEDIDO!$B:$C,2,0),"") | M140: =IF(N(L140)>0,"COMPRA","NÃO COMPRA") -> NÃO COMPRA
A141: 582460141 | C141: ANEL PISTÃO 106/206/307/C3 1.6 16V STD | D141: LEVE | E141: ANEL DE PISTAO | F141: PEUGEOT / CITROEN | G141: C | H141: 2C9369 (HASTINGS) 800101340 (KS) A44500 (MAHLE) A640 (SINTECH) LDS.8108 (METAL LEVE) | J141: 4 CILINDROS | L141: =IFERROR(VLOOKUP(A141,PEDIDO!$B:$C,2,0),"") | M141: =IF(N(L141)>0,"COMPRA","NÃO COMPRA") -> NÃO COMPRA
A142: 582885401 | C142: ANEL PISTÃO GM ONIX / PRISMA 1.4 8V FLEX 050 | D142: LEVE | E142: ANEL DE PISTAO | F142: CHEVROLET | G142: C | H142: 2C4354 (HASTINGS) A0141150 (MAHLE) A0142050 (MAHLE) A155 (SINTECH) TA.9021 (METAL LEVE) | J142: 4 CILINDROS | L142: =IFERROR(VLOOKUP(A142,PEDIDO!$B:$C,2,0),"") | M142: =IF(N(L142)>0,"COMPRA","NÃO COMPRA") -> NÃO COMPRA
A143: 583200201 | C143: ANEL DE PISTÃO MERCEDES OM447 LA / OM449 A / OM449 LA | D143: PESADO | E143: ANEL DE PISTAO | F143: MERCEDES BENZ | G143: C | H143: 13012801-00 (POWER SEAL) 2D7096 (HASTINGS) 800019510000 (KS) A4220300024 (ORIG.) A4220300124 (ORIG.) A48930 (MAHLE) GC.6926 (METAL LEVE) | J143: 5 / 6 CILINDROS | L143: =IFERROR(VLOOKUP(A143,PEDIDO!$B:$C,2,0),"") | M143: =IF(N(L143)>0,"COMPRA","NÃO COMPRA") -> NÃO COMPRA
A144: 583120901 | C144: ANEL DE PISTÃO SCANIA DC11/12/16/ DS12 / DSC11/1 | D144: PESADO | E144: ANEL DE PISTAO | F144: SCANIA | G144: C | H144: A76680 (MAHLE) | J144: 4 CILINDROS | L144: =IFERROR(VLOOKUP(A144,PEDIDO!$B:$C,2,0),"") | M144: =IF(N(L144)>0,"COMPRA","NÃO COMPRA") -> NÃO COMPRA
A145: 583560201 | C145: ANEL E PISTÃO MERCEDES OM924 LA / OM926 LA - EURO | D145: PESADO | E145: ANEL DE PISTAO | F145: MERCEDES BENZ | G145: C | H145: A0481040 (MAHLE) | J145: 4 / 6 CILINDROS | L145: =IFERROR(VLOOKUP(A145,PEDIDO!$B:$C,2,0),"") | M145: =IF(N(L145)>0,"COMPRA","NÃO COMPRA") -> NÃO COMPRA
A146: 580785101 | C146: ANEL PISTÃO VW GOL 1.6 8V +050 (LL) | D146: LEVE | E146: ANEL DE PISTAO | F146: VOLKSWAGEN | G146: C | H146: 4490020 (HASTINGS) 800000946 (KS) A70670 (MAHLE) A70679 (SPA MAHLE) ASVW16E-050 (TAKAO) DA6075 (METAL LEVE) PNA7809 (CENTRINEL) SNA6075 (SPA METAL LEVE) | J146: 4 CILINDROS | L146: =IFERROR(VLOOKUP(A146,PEDIDO!$B:$C,2,0),"") | M146: =IF(N(L146)>0,"COMPRA","NÃO COMPRA") -> NÃO COMPRA
A147: 580360101 | C147: ANEL PISTÃO VW FUSCA/KOMBI 1.6 (AR) STD (LL) | D147: LEVE | E147: ANEL DE PISTAO | F147: VOLKSWAGEN | G147: C | H147: 2C4841 (HASTINGS) 800026742 (KS) A70152 (MAHLE) A70153 (MAHLE) A70159 (SPA MAHLE) ASVW16-STD (TAKAO) CA2297 (METAL LEVE) NA2297 (METAL LEVE) PMA7811 (CENTRINEL) SNA2297 (SPA METAL LEVE) | J147: 4 CILINDROS | L147: =IFERROR(VLOOKUP(A147,PEDIDO!$B:$C,2,0),"") | M147: =IF(N(L147)>0,"COMPRA","NÃO COMPRA") -> NÃO COMPRA
A148: 583460201 | C148: ANEL DE PISTÃO MERCEDES OM924 LA / OM926 LA | D148: PESADO | E148: ANEL DE PISTAO | F148: MERCEDES BENZ | G148: C | H148: A48690 (MAHLE) | J148: 4 / 6 CILINDROS | L148: =IFERROR(VLOOKUP(A148,PEDIDO!$B:$C,2,0),"") | M148: =IF(N(L148)>0,"COMPRA","NÃO COMPRA") -> NÃO COMPRA
A149: 583550801 | C149: ANEL DE PISTÃO MWM 4.10 / 6.10 | D149: PESADO | E149: ANEL DE PISTAO | F149: MWM | G149: C | H149: A13900 (MAHLE) | L149: =IFERROR(VLOOKUP(A149,PEDIDO!$B:$C,2,0),"") | M149: =IF(N(L149)>0,"COMPRA","NÃO COMPRA") -> NÃO COMPRA
A150: 583510801 | C150: ANEL DE ISTÃO MWM D229 / TD229 / TD229-EC | D150: PESADO | E150: ANEL DE PISTAO | F150: MWM | G150: C | H150: A13850 (MAHLE) | J150: 6 CILINDROS | L150: =IFERROR(VLOOKUP(A150,PEDIDO!$B:$C,2,0),"") | M150: =IF(N(L150)>0,"COMPRA","NÃO COMPRA") -> NÃO COMPRA
A151: 583400701 | C151: ANEL DE PISTÃO IVECO CURSOR 13 / EURO 3 | D151: PESADO | E151: ANEL DE PISTAO | F151: FIAT | G151: C | H151: A01210 (MAHLE) | J151: 6 CILINDROS | L151: =IFERROR(VLOOKUP(A151,PEDIDO!$B:$C,2,0),"") | M151: =IF(N(L151)>0,"COMPRA","NÃO COMPRA") -> NÃO COMPRA
A152: 581395101 | C152: ANEL PISTÃO PEUGEOT 206/C3 1.4 8V +050 (LL) | D152: LEVE | E152: ANEL DE PISTAO | F152: PEUGEOT / CITROEN | G152: C | H152: 2C5021020 (HASTINGS) A44060 (MAHLE) A620 050 (SINTECH) CMA8724 (CENTRINEL) DA8411 (METAL LEVE) | J152: 4 CILINDROS | L152: =IFERROR(VLOOKUP(A152,PEDIDO!$B:$C,2,0),"") | M152: =IF(N(L152)>0,"COMPRA","NÃO COMPRA") -> NÃO COMPRA
A153: 582535641 | C153: ANEL PISTÃO TUCSON / I30 MOTOR G4GF 2.0 16V 050 | D153: LEVE | E153: ANEL DE PISTAO | F153: KIA MOTORS | G153: C | H153: 2C5825020 (HASTINGS) A208150 (MAHLE) A300 (SINTECH) AA.8812 (METAL LEVE) | J153: 4 CILINDROS | L153: =IFERROR(VLOOKUP(A153,PEDIDO!$B:$C,2,0),"") | M153: =IF(N(L153)>0,"COMPRA","NÃO COMPRA") -> NÃO COMPRA
A154: 583300691 | C154: ANEL PISTÃO PERKINS 1104C ASPIRADO | D154: PESADO | E154: ANEL DE PISTAO | F154: PERKINS | G154: C | H154: 18510502-00 (POWER SEAL) 3136L031 (ORIG.) 3136L035 (ORIG.) 3137L045 (ORIG.) 4115P511 (ORIG.) 4115P521 (ORIG.) 800078810000 (KS) A0571010 (MAHLE) LC.8768 (METAL LEVE) | L154: =IFERROR(VLOOKUP(A154,PEDIDO!$B:$C,2,0),"") | M154: =IF(N(L154)>0,"COMPRA","NÃO COMPRA") -> NÃO COMPRA
...

Sheet PEDIDO
A1: CÓDIGO (cole aqui como veio no pedido) | B1: CÓDIGO (tratado) | C1: QUANTIDADE
B2: =IFERROR(--SUBSTITUTE(TRIM(A2)," ",""),SUBSTITUTE(TRIM(A2)," ",""))
B3: =IFERROR(--SUBSTITUTE(TRIM(A3)," ",""),SUBSTITUTE(TRIM(A3)," ",""))
B4: =IFERROR(--SUBSTITUTE(TRIM(A4)," ",""),SUBSTITUTE(TRIM(A4)," ",""))
B5: =IFERROR(--SUBSTITUTE(TRIM(A5)," ",""),SUBSTITUTE(TRIM(A5)," ",""))
B6: =IFERROR(--SUBSTITUTE(TRIM(A6)," ",""),SUBSTITUTE(TRIM(A6)," ",""))
B7: =IFERROR(--SUBSTITUTE(TRIM(A7)," ",""),SUBSTITUTE(TRIM(A7)," ",""))
B8: =IFERROR(--SUBSTITUTE(TRIM(A8)," ",""),SUBSTITUTE(TRIM(A8)," ",""))
B9: =IFERROR(--SUBSTITUTE(TRIM(A9)," ",""),SUBSTITUTE(TRIM(A9)," ",""))
B10: =IFERROR(--SUBSTITUTE(TRIM(A10)," ",""),SUBSTITUTE(TRIM(A10)," ",""))
B11: =IFERROR(--SUBSTITUTE(TRIM(A11)," ",""),SUBSTITUTE(TRIM(A11)," ",""))
B12: =IFERROR(--SUBSTITUTE(TRIM(A12)," ",""),SUBSTITUTE(TRIM(A12)," ",""))
B13: =IFERROR(--SUBSTITUTE(TRIM(A13)," ",""),SUBSTITUTE(TRIM(A13)," ",""))
... B501: =IFERROR(--SUBSTITUTE(TRIM(A501)," ",""),SUBSTITUTE(TRIM(A501)," ",""))
